Workbook

Sheet Sheet1
A1: {=IF(_xlfn.UNIQUE(_xlfn._xlws.FILTER(CONCATENATE(RAW_DATA!A:A,RAW_DATA!B:B,RAW_DATA!C:C),1))<>"",_xlfn.UNIQUE(_xlfn._xlws.FILTER(CONCATENATE(RAW_DATA!A:A,RAW_DATA!B:B,RAW_DATA!C:C),1)),NA())} -> SubjectIDStudy_NameMovement | B1: Horizontal N | C1: Vertical N | D1: Pupil N | E1: =RAW_DATA!X1 -> Binocular_Gain_Horizontal | F1: =RAW_DATA!Y1 -> Binocular_Gain_Vertical | G1: =RAW_DATA!Z1 -> Binocular_Gain_Pupil | H1: Horizontal Blink In Transient Average | I1: Vertical Blink In Transient Average | J1: Pupil Blink In Transient Average | K1: Horizontal Blink Count Average | L1: Vertical Blink Count Average | M1: Pupil Blink Count Average | N1: =RAW_DATA!G1 -> Binocular_RSI | O1: =RAW_DATA!H1 -> Binocular_REI | P1: =RAW_DATA!I1 -> Binocular_RA | Q1: =RAW_DATA!J1 -> Binocular_PVI | R1: =RAW_DATA!K1 -> Binocular_PV | S1: =RAW_DATA!L1 -> Binocular_FA | T1: =RAW_DATA!M1 -> Binocular_RSID | U1: =RAW_DATA!N1 -> Binocular_REID | ... Z1: =RAW_DATA!S1 -> Binocular_ID
A2: Control1AXNPPCSBattery4_8_CONV_STEP | B2: {=IF(ISERR(SUM(_xlfn._xlws.FILTER(RAW_DATA!$T:$T,EXACT(_xlfn._xlws.FILTER(CONCATENATE(RAW_DATA!$A:$A,RAW_DATA!$B:$B,RAW_DATA!$C:$C),1),$A2)))),"",SUM(_xlfn._xlws.FILTER(RAW_DATA!$T:$T,EXACT(_xlfn._xlws.FILTER(CONCATENATE(RAW_DATA!$A:$A,RAW_DATA!$B:$B,RAW_DATA!$C:$C),1),$A2))))} -> 0 | C2: {=IF(ISERR(SUM(_xlfn._xlws.FILTER(RAW_DATA!$U:$U,EXACT(_xlfn._xlws.FILTER(CONCATENATE(RAW_DATA!$A:$A,RAW_DATA!$B:$B,RAW_DATA!$C:$C),1),$A2)))),"",SUM(_xlfn._xlws.FILTER(RAW_DATA!$U:$U,EXACT(_xlfn._xlws.FILTER(CONCATENATE(RAW_DATA!$A:$A,RAW_DATA!$B:$B,RAW_DATA!$C:$C),1),$A2))))} -> 0 | D2: {=IF(ISERR(SUM(_xlfn._xlws.FILTER(RAW_DATA!$V:$V,EXACT(_xlfn._xlws.FILTER(CONCATENATE(RAW_DATA!$A:$A,RAW_DATA!$B:$B,RAW_DATA!$C:$C),1),$A2)))),"",SUM(_xlfn._xlws.FILTER(RAW_DATA!$V:$V,EXACT(_xlfn._xlws.FILTER(CONCATENATE(RAW_DATA!$A:$A,RAW_DATA!$B:$B,RAW_DATA!$C:$C),1),$A2))))} -> 10 | E2: {=IF(ISERR(SUM(_xlfn._xlws.FILTER(RAW_DATA!$X:$X,EXACT(_xlfn._xlws.FILTER(CONCATENATE(RAW_DATA!$A:$A,RAW_DATA!$B:$B,RAW_DATA!$C:$C),1),$A2)*(RAW_DATA!$T:$T=1)))/$B2),"",SUM(_xlfn._xlws.FILTER(RAW_DATA!$X:$X,EXACT(_xlfn._xlws.FILTER(CONCATENATE(RAW_DATA!$A:$A,RAW_DATA!$B:$B,RAW_DATA!$C:$C),1),$A2)*(RAW_DATA!$T:$T=1)))/$B2)} | F2: {=IF(ISERR(SUM(_xlfn._xlws.FILTER(RAW_DATA!$Y:$Y,EXACT(_xlfn._xlws.FILTER(CONCATENATE(RAW_DATA!$A:$A,RAW_DATA!$B:$B,RAW_DATA!$C:$C),1),$A2)*(RAW_DATA!$U:$U=1)))/$C2),"",SUM(_xlfn._xlws.FILTER(RAW_DATA!$Y:$Y,EXACT(_xlfn._xlws.FILTER(CONCATENATE(RAW_DATA!$A:$A,RAW_DATA!$B:$B,RAW_DATA!$C:$C),1),$A2)*(RAW_DATA!$U:$U=1)))/$C2)} | G2: {=IF(ISERR(SUM(_xlfn._xlws.FILTER(RAW_DATA!$Z:$Z,EXACT(_xlfn._xlws.FILTER(CONCATENATE(RAW_DATA!$A:$A,RAW_DATA!$B:$B,RAW_DATA!$C:$C),1),$A2)*(RAW_DATA!$V:$V=1)))/$D2),"",SUM(_xlfn._xlws.FILTER(RAW_DATA!$Z:$Z,EXACT(_xlfn._xlws.FILTER(CONCATENATE(RAW_DATA!$A:$A,RAW_DATA!$B:$B,RAW_DATA!$C:$C),1),$A2)*(RAW_DATA!$V:$V=1)))/$D2)} -> 20.1925 | H2: {=IF(ISERR(SUM(_xlfn._xlws.FILTER(RAW_DATA!$E:$E,EXACT(_xlfn._xlws.FILTER(CONCATENATE(RAW_DATA!$A:$A,RAW_DATA!$B:$B,RAW_DATA!$C:$C),1),$A2)*(RAW_DATA!T:T=1)))/$B2),"",SUM(_xlfn._xlws.FILTER(RAW_DATA!$E:$E,EXACT(_xlfn._xlws.FILTER(CONCATENATE(RAW_DATA!$A:$A,RAW_DATA!$B:$B,RAW_DATA!$C:$C),1),$A2)*(RAW_DATA!T:T=1)))/$B2)} | I2: {=IF(ISERR(SUM(_xlfn._xlws.FILTER(RAW_DATA!$E:$E,EXACT(_xlfn._xlws.FILTER(CONCATENATE(RAW_DATA!$A:$A,RAW_DATA!$B:$B,RAW_DATA!$C:$C),1),$A2)*(RAW_DATA!U:U=1)))/$C2),"",SUM(_xlfn._xlws.FILTER(RAW_DATA!$E:$E,EXACT(_xlfn._xlws.FILTER(CONCATENATE(RAW_DATA!$A:$A,RAW_DATA!$B:$B,RAW_DATA!$C:$C),1),$A2)*(RAW_DATA!U:U=1)))/$C2)} | J2: {=IF(ISERR(SUM(_xlfn._xlws.FILTER(RAW_DATA!$E:$E,EXACT(_xlfn._xlws.FILTER(CONCATENATE(RAW_DATA!$A:$A,RAW_DATA!$B:$B,RAW_DATA!$C:$C),1),$A2)*(RAW_DATA!V:V=1)))/$D2),"",SUM(_xlfn._xlws.FILTER(RAW_DATA!$E:$E,EXACT(_xlfn._xlws.FILTER(CONCATENATE(RAW_DATA!$A:$A,RAW_DATA!$B:$B,RAW_DATA!$C:$C),1),$A2)*(RAW_DATA!V:V=1)))/$D2)} -> 0 | K2: {=IF(ISERR(SUM(_xlfn._xlws.FILTER(RAW_DATA!$F:$F,EXACT(_xlfn._xlws.FILTER(CONCATENATE(RAW_DATA!$A:$A,RAW_DATA!$B:$B,RAW_DATA!$C:$C),1),$A2)*(RAW_DATA!T:T=1)))/$B2),"",SUM(_xlfn._xlws.FILTER(RAW_DATA!$F:$F,EXACT(_xlfn._xlws.FILTER(CONCATENATE(RAW_DATA!$A:$A,RAW_DATA!$B:$B,RAW_DATA!$C:$C),1),$A2)*(RAW_DATA!T:T=1)))/$B2)} | L2: {=IF(ISERR(SUM(_xlfn._xlws.FILTER(RAW_DATA!$F:$F,EXACT(_xlfn._xlws.FILTER(CONCATENATE(RAW_DATA!$A:$A,RAW_DATA!$B:$B,RAW_DATA!$C:$C),1),$A2)*(RAW_DATA!U:U=1)))/$C2),"",SUM(_xlfn._xlws.FILTER(RAW_DATA!$F:$F,EXACT(_xlfn._xlws.FILTER(CONCATENATE(RAW_DATA!$A:$A,RAW_DATA!$B:$B,RAW_DATA!$C:$C),1),$A2)*(RAW_DATA!U:U=1)))/$C2)} | M2: {=IF(ISERR(SUM(_xlfn._xlws.FILTER(RAW_DATA!$F:$F,EXACT(_xlfn._xlws.FILTER(CONCATENATE(RAW_DATA!$A:$A,RAW_DATA!$B:$B,RAW_DATA!$C:$C),1),$A2)*(RAW_DATA!V:V=1)))/$D2),"",SUM(_xlfn._xlws.FILTER(RAW_DATA!$F:$F,EXACT(_xlfn._xlws.FILTER(CONCATENATE(RAW_DATA!$A:$A,RAW_DATA!$B:$B,RAW_DATA!$C:$C),1),$A2)*(RAW_DATA!V:V=1)))/$D2)} -> 0 | N2: {=IF(ISERR(SUM(_xlfn._xlws.FILTER(RAW_DATA!G:G,EXACT(_xlfn._xlws.FILTER(CONCATENATE(RAW_DATA!$A:$A,RAW_DATA!$B:$B,RAW_DATA!$C:$C),1),$A2)*(RAW_DATA!$T:$T=1)))/$B2),"",SUM(_xlfn._xlws.FILTER(RAW_DATA!G:G,EXACT(_xlfn._xlws.FILTER(CONCATENATE(RAW_DATA!$A:$A,RAW_DATA!$B:$B,RAW_DATA!$C:$C),1),$A2)*(RAW_DATA!$T:$T=1)))/$B2)} | O2: {=IF(ISERR(SUM(_xlfn._xlws.FILTER(RAW_DATA!H:H,EXACT(_xlfn._xlws.FILTER(CONCATENATE(RAW_DATA!$A:$A,RAW_DATA!$B:$B,RAW_DATA!$C:$C),1),$A2)*(RAW_DATA!$T:$T=1)))/$B2),"",SUM(_xlfn._xlws.FILTER(RAW_DATA!H:H,EXACT(_xlfn._xlws.FILTER(CONCATENATE(RAW_DATA!$A:$A,RAW_DATA!$B:$B,RAW_DATA!$C:$C),1),$A2)*(RAW_DATA!$T:$T=1)))/$B2)} | P2: {=IF(ISERR(SUM(_xlfn._xlws.FILTER(RAW_DATA!I:I,EXACT(_xlfn._xlws.FILTER(CONCATENATE(RAW_DATA!$A:$A,RAW_DATA!$B:$B,RAW_DATA!$C:$C),1),$A2)*(RAW_DATA!$T:$T=1)))/$B2),"",SUM(_xlfn._xlws.FILTER(RAW_DATA!I:I,EXACT(_xlfn._xlws.FILTER(CONCATENATE(RAW_DATA!$A:$A,RAW_DATA!$B:$B,RAW_DATA!$C:$C),1),$A2)*(RAW_DATA!$T:$T=1)))/$B2)} | Q2: {=IF(ISERR(SUM(_xlfn._xlws.FILTER(RAW_DATA!J:J,EXACT(_xlfn._xlws.FILTER(CONCATENATE(RAW_DATA!$A:$A,RAW_DATA!$B:$B,RAW_DATA!$C:$C),1),$A2)*(RAW_DATA!$T:$T=1)))/$B2),"",SUM(_xlfn._xlws.FILTER(RAW_DATA!J:J,EXACT(_xlfn._xlws.FILTER(CONCATENATE(RAW_DATA!$A:$A,RAW_DATA!$B:$B,RAW_DATA!$C:$C),1),$A2)*(RAW_DATA!$T:$T=1)))/$B2)} | R2: {=IF(ISERR(SUM(_xlfn._xlws.FILTER(RAW_DATA!K:K,EXACT(_xlfn._xlws.FILTER(CONCATENATE(RAW_DATA!$A:$A,RAW_DATA!$B:$B,RAW_DATA!$C:$C),1),$A2)*(RAW_DATA!$T:$T=1)))/$B2),"",SUM(_xlfn._xlws.FILTER(RAW_DATA!K:K,EXACT(_xlfn._xlws.FILTER(CONCATENATE(RAW_DATA!$A:$A,RAW_DATA!$B:$B,RAW_DATA!$C:$C),1),$A2)*(RAW_DATA!$T:$T=1)))/$B2)} | S2: {=IF(ISERR(SUM(_xlfn._xlws.FILTER(RAW_DATA!L:L,EXACT(_xlfn._xlws.FILTER(CONCATENATE(RAW_DATA!$A:$A,RAW_DATA!$B:$B,RAW_DATA!$C:$C),1),$A2)*(RAW_DATA!$T:$T=1)))/$B2),"",SUM(_xlfn._xlws.FILTER(RAW_DATA!L:L,EXACT(_xlfn._xlws.FILTER(CONCATENATE(RAW_DATA!$A:$A,RAW_DATA!$B:$B,RAW_DATA!$C:$C),1),$A2)*(RAW_DATA!$T:$T=1)))/$B2)} | T2: {=IF(ISERR(SUM(_xlfn._xlws.FILTER(RAW_DATA!M:M,EXACT(_xlfn._xlws.FILTER(CONCATENATE(RAW_DATA!$A:$A,RAW_DATA!$B:$B,RAW_DATA!$C:$C),1),$A2)*(RAW_DATA!$V:$V=1)))/$D2),"",SUM(_xlfn._xlws.FILTER(RAW_DATA!M:M,EXACT(_xlfn._xlws.FILTER(CONCATENATE(RAW_DATA!$A:$A,RAW_DATA!$B:$B,RAW_DATA!$C:$C),1),$A2)*(RAW_DATA!$V:$V=1)))/$D2)} -> 1.1988 | U2: {=IF(ISERR(SUM(_xlfn._xlws.FILTER(RAW_DATA!N:N,EXACT(_xlfn._xlws.FILTER(CONCATENATE(RAW_DATA!$A:$A,RAW_DATA!$B:$B,RAW_DATA!$C:$C),1),$A2)*(RAW_DATA!$V:$V=1)))/$D2),"",SUM(_xlfn._xlws.FILTER(RAW_DATA!N:N,EXACT(_xlfn._xlws.FILTER(CONCATENATE(RAW_DATA!$A:$A,RAW_DATA!$B:$B,RAW_DATA!$C:$C),1),$A2)*(RAW_DATA!$V:$V=1)))/$D2)} -> 1.756 | V2: {=IF(ISERR(SUM(_xlfn._xlws.FILTER(RAW_DATA!O:O,EXACT(_xlfn._xlws.FILTER(CONCATENATE(RAW_DATA!$A:$A,RAW_DATA!$B:$B,RAW_DATA!$C:$C),1),$A2)*(RAW_DATA!$V:$V=1)))/$D2),"",SUM(_xlfn._xlws.FILTER(RAW_DATA!O:O,EXACT(_xlfn._xlws.FILTER(CONCATENATE(RAW_DATA!$A:$A,RAW_DATA!$B:$B,RAW_DATA!$C:$C),1),$A2)*(RAW_DATA!$V:$V=1)))/$D2)} -> -0.414686 | W2: {=IF(ISERR(SUM(_xlfn._xlws.FILTER(RAW_DATA!P:P,EXACT(_xlfn._xlws.FILTER(CONCATENATE(RAW_DATA!$A:$A,RAW_DATA!$B:$B,RAW_DATA!$C:$C),1),$A2)*(RAW_DATA!$V:$V=1)))/$D2),"",SUM(_xlfn._xlws.FILTER(RAW_DATA!P:P,EXACT(_xlfn._xlws.FILTER(CONCATENATE(RAW_DATA!$A:$A,RAW_DATA!$B:$B,RAW_DATA!$C:$C),1),$A2)*(RAW_DATA!$V:$V=1)))/$D2)} -> 1.4668 | X2: {=IF(ISERR(SUM(_xlfn._xlws.FILTER(RAW_DATA!Q:Q,EXACT(_xlfn._xlws.FILTER(CONCATENATE(RAW_DATA!$A:$A,RAW_DATA!$B:$B,RAW_DATA!$C:$C),1),$A2)*(RAW_DATA!$V:$V=1)))/$D2),"",SUM(_xlfn._xlws.FILTER(RAW_DATA!Q:Q,EXACT(_xlfn._xlws.FILTER(CONCATENATE(RAW_DATA!$A:$A,RAW_DATA!$B:$B,RAW_DATA!$C:$C),1),$A2)*(RAW_DATA!$V:$V=1)))/$D2)} -> 3.88158 | Y2: {=IF(ISERR(SUM(_xlfn._xlws.FILTER(RAW_DATA!R:R,EXACT(_xlfn._xlws.FILTER(CONCATENATE(RAW_DATA!$A:$A,RAW_DATA!$B:$B,RAW_DATA!$C:$C),1),$A2)*(RAW_DATA!$V:$V=1)))/$D2),"",SUM(_xlfn._xlws.FILTER(RAW_DATA!R:R,EXACT(_xlfn._xlws.FILTER(CONCATENATE(RAW_DATA!$A:$A,RAW_DATA!$B:$B,RAW_DATA!$C:$C),1),$A2)*(RAW_DATA!$V:$V=1)))/$D2)} -> 0.3176 | Z2: {=IF(ISERR(SUM(_xlfn._xlws.FILTER(RAW_DATA!S:S,EXACT(_xlfn._xlws.FILTER(CONCATENATE(RAW_DATA!$A:$A,RAW_DATA!$B:$B,RAW_DATA!$C:$C),1),$A2)*(RAW_DATA!$V:$V=1)))/$D2),"",SUM(_xlfn._xlws.FILTER(RAW_DATA!S:S,EXACT(_xlfn._xlws.FILTER(CONCATENATE(RAW_DATA!$A:$A,RAW_DATA!$B:$B,RAW_DATA!$C:$C),1),$A2)*(RAW_DATA!$V:$V=1)))/$D2)} -> 0
A3: Control4EGGPPCSBattery4_8_CONV_STEP | B3: {=IF(ISERR(SUM(_xlfn._xlws.FILTER(RAW_DATA!$T:$T,EXACT(_xlfn._xlws.FILTER(CONCATENATE(RAW_DATA!$A:$A,RAW_DATA!$B:$B,RAW_DATA!$C:$C),1),$A3)))),"",SUM(_xlfn._xlws.FILTER(RAW_DATA!$T:$T,EXACT(_xlfn._xlws.FILTER(CONCATENATE(RAW_DATA!$A:$A,RAW_DATA!$B:$B,RAW_DATA!$C:$C),1),$A3))))} -> 0 | C3: {=IF(ISERR(SUM(_xlfn._xlws.FILTER(RAW_DATA!$U:$U,EXACT(_xlfn._xlws.FILTER(CONCATENATE(RAW_DATA!$A:$A,RAW_DATA!$B:$B,RAW_DATA!$C:$C),1),$A3)))),"",SUM(_xlfn._xlws.FILTER(RAW_DATA!$U:$U,EXACT(_xlfn._xlws.FILTER(CONCATENATE(RAW_DATA!$A:$A,RAW_DATA!$B:$B,RAW_DATA!$C:$C),1),$A3))))} -> 0 | D3: {=IF(ISERR(SUM(_xlfn._xlws.FILTER(RAW_DATA!$V:$V,EXACT(_xlfn._xlws.FILTER(CONCATENATE(RAW_DATA!$A:$A,RAW_DATA!$B:$B,RAW_DATA!$C:$C),1),$A3)))),"",SUM(_xlfn._xlws.FILTER(RAW_DATA!$V:$V,EXACT(_xlfn._xlws.FILTER(CONCATENATE(RAW_DATA!$A:$A,RAW_DATA!$B:$B,RAW_DATA!$C:$C),1),$A3))))} -> 9 | E3: {=IF(ISERR(SUM(_xlfn._xlws.FILTER(RAW_DATA!$X:$X,EXACT(_xlfn._xlws.FILTER(CONCATENATE(RAW_DATA!$A:$A,RAW_DATA!$B:$B,RAW_DATA!$C:$C),1),$A3)*(RAW_DATA!$T:$T=1)))/$B3),"",SUM(_xlfn._xlws.FILTER(RAW_DATA!$X:$X,EXACT(_xlfn._xlws.FILTER(CONCATENATE(RAW_DATA!$A:$A,RAW_DATA!$B:$B,RAW_DATA!$C:$C),1),$A3)*(RAW_DATA!$T:$T=1)))/$B3)} | F3: {=IF(ISERR(SUM(_xlfn._xlws.FILTER(RAW_DATA!$Y:$Y,EXACT(_xlfn._xlws.FILTER(CONCATENATE(RAW_DATA!$A:$A,RAW_DATA!$B:$B,RAW_DATA!$C:$C),1),$A3)*(RAW_DATA!$U:$U=1)))/$C3),"",SUM(_xlfn._xlws.FILTER(RAW_DATA!$Y:$Y,EXACT(_xlfn._xlws.FILTER(CONCATENATE(RAW_DATA!$A:$A,RAW_DATA!$B:$B,RAW_DATA!$C:$C),1),$A3)*(RAW_DATA!$U:$U=1)))/$C3)} | G3: {=IF(ISERR(SUM(_xlfn._xlws.FILTER(RAW_DATA!$Z:$Z,EXACT(_xlfn._xlws.FILTER(CONCATENATE(RAW_DATA!$A:$A,RAW_DATA!$B:$B,RAW_DATA!$C:$C),1),$A3)*(RAW_DATA!$V:$V=1)))/$D3),"",SUM(_xlfn._xlws.FILTER(RAW_DATA!$Z:$Z,EXACT(_xlfn._xlws.FILTER(CONCATENATE(RAW_DATA!$A:$A,RAW_DATA!$B:$B,RAW_DATA!$C:$C),1),$A3)*(RAW_DATA!$V:$V=1)))/$D3)} -> 20.1925 | H3: {=IF(ISERR(SUM(_xlfn._xlws.FILTER(RAW_DATA!$E:$E,EXACT(_xlfn._xlws.FILTER(CONCATENATE(RAW_DATA!$A:$A,RAW_DATA!$B:$B,RAW_DATA!$C:$C),1),$A3)*(RAW_DATA!T:T=1)))/$B3),"",SUM(_xlfn._xlws.FILTER(RAW_DATA!$E:$E,EXACT(_xlfn._xlws.FILTER(CONCATENATE(RAW_DATA!$A:$A,RAW_DATA!$B:$B,RAW_DATA!$C:$C),1),$A3)*(RAW_DATA!T:T=1)))/$B3)} | I3: {=IF(ISERR(SUM(_xlfn._xlws.FILTER(RAW_DATA!$E:$E,EXACT(_xlfn._xlws.FILTER(CONCATENATE(RAW_DATA!$A:$A,RAW_DATA!$B:$B,RAW_DATA!$C:$C),1),$A3)*(RAW_DATA!U:U=1)))/$C3),"",SUM(_xlfn._xlws.FILTER(RAW_DATA!$E:$E,EXACT(_xlfn._xlws.FILTER(CONCATENATE(RAW_DATA!$A:$A,RAW_DATA!$B:$B,RAW_DATA!$C:$C),1),$A3)*(RAW_DATA!U:U=1)))/$C3)} | J3: {=IF(ISERR(SUM(_xlfn._xlws.FILTER(RAW_DATA!$E:$E,EXACT(_xlfn._xlws.FILTER(CONCATENATE(RAW_DATA!$A:$A,RAW_DATA!$B:$B,RAW_DATA!$C:$C),1),$A3)*(RAW_DATA!V:V=1)))/$D3),"",SUM(_xlfn._xlws.FILTER(RAW_DATA!$E:$E,EXACT(_xlfn._xlws.FILTER(CONCATENATE(RAW_DATA!$A:$A,RAW_DATA!$B:$B,RAW_DATA!$C:$C),1),$A3)*(RAW_DATA!V:V=1)))/$D3)} -> 0 | K3: {=IF(ISERR(SUM(_xlfn._xlws.FILTER(RAW_DATA!$F:$F,EXACT(_xlfn._xlws.FILTER(CONCATENATE(RAW_DATA!$A:$A,RAW_DATA!$B:$B,RAW_DATA!$C:$C),1),$A3)*(RAW_DATA!T:T=1)))/$B3),"",SUM(_xlfn._xlws.FILTER(RAW_DATA!$F:$F,EXACT(_xlfn._xlws.FILTER(CONCATENATE(RAW_DATA!$A:$A,RAW_DATA!$B:$B,RAW_DATA!$C:$C),1),$A3)*(RAW_DATA!T:T=1)))/$B3)} | L3: {=IF(ISERR(SUM(_xlfn._xlws.FILTER(RAW_DATA!$F:$F,EXACT(_xlfn._xlws.FILTER(CONCATENATE(RAW_DATA!$A:$A,RAW_DATA!$B:$B,RAW_DATA!$C:$C),1),$A3)*(RAW_DATA!U:U=1)))/$C3),"",SUM(_xlfn._xlws.FILTER(RAW_DATA!$F:$F,EXACT(_xlfn._xlws.FILTER(CONCATENATE(RAW_DATA!$A:$A,RAW_DATA!$B:$B,RAW_DATA!$C:$C),1),$A3)*(RAW_DATA!U:U=1)))/$C3)} | M3: {=IF(ISERR(SUM(_xlfn._xlws.FILTER(RAW_DATA!$F:$F,EXACT(_xlfn._xlws.FILTER(CONCATENATE(RAW_DATA!$A:$A,RAW_DATA!$B:$B,RAW_DATA!$C:$C),1),$A3)*(RAW_DATA!V:V=1)))/$D3),"",SUM(_xlfn._xlws.FILTER(RAW_DATA!$F:$F,EXACT(_xlfn._xlws.FILTER(CONCATENATE(RAW_DATA!$A:$A,RAW_DATA!$B:$B,RAW_DATA!$C:$C),1),$A3)*(RAW_DATA!V:V=1)))/$D3)} -> 0.11111111 | N3: {=IF(ISERR(SUM(_xlfn._xlws.FILTER(RAW_DATA!G:G,EXACT(_xlfn._xlws.FILTER(CONCATENATE(RAW_DATA!$A:$A,RAW_DATA!$B:$B,RAW_DATA!$C:$C),1),$A3)*(RAW_DATA!$T:$T=1)))/$B3),"",SUM(_xlfn._xlws.FILTER(RAW_DATA!G:G,EXACT(_xlfn._xlws.FILTER(CONCATENATE(RAW_DATA!$A:$A,RAW_DATA!$B:$B,RAW_DATA!$C:$C),1),$A3)*(RAW_DATA!$T:$T=1)))/$B3)} | O3: {=IF(ISERR(SUM(_xlfn._xlws.FILTER(RAW_DATA!H:H,EXACT(_xlfn._xlws.FILTER(CONCATENATE(RAW_DATA!$A:$A,RAW_DATA!$B:$B,RAW_DATA!$C:$C),1),$A3)*(RAW_DATA!$T:$T=1)))/$B3),"",SUM(_xlfn._xlws.FILTER(RAW_DATA!H:H,EXACT(_xlfn._xlws.FILTER(CONCATENATE(RAW_DATA!$A:$A,RAW_DATA!$B:$B,RAW_DATA!$C:$C),1),$A3)*(RAW_DATA!$T:$T=1)))/$B3)} | P3: {=IF(ISERR(SUM(_xlfn._xlws.FILTER(RAW_DATA!I:I,EXACT(_xlfn._xlws.FILTER(CONCATENATE(RAW_DATA!$A:$A,RAW_DATA!$B:$B,RAW_DATA!$C:$C),1),$A3)*(RAW_DATA!$T:$T=1)))/$B3),"",SUM(_xlfn._xlws.FILTER(RAW_DATA!I:I,EXACT(_xlfn._xlws.FILTER(CONCATENATE(RAW_DATA!$A:$A,RAW_DATA!$B:$B,RAW_DATA!$C:$C),1),$A3)*(RAW_DATA!$T:$T=1)))/$B3)} | Q3: {=IF(ISERR(SUM(_xlfn._xlws.FILTER(RAW_DATA!J:J,EXACT(_xlfn._xlws.FILTER(CONCATENATE(RAW_DATA!$A:$A,RAW_DATA!$B:$B,RAW_DATA!$C:$C),1),$A3)*(RAW_DATA!$T:$T=1)))/$B3),"",SUM(_xlfn._xlws.FILTER(RAW_DATA!J:J,EXACT(_xlfn._xlws.FILTER(CONCATENATE(RAW_DATA!$A:$A,RAW_DATA!$B:$B,RAW_DATA!$C:$C),1),$A3)*(RAW_DATA!$T:$T=1)))/$B3)} | R3: {=IF(ISERR(SUM(_xlfn._xlws.FILTER(RAW_DATA!K:K,EXACT(_xlfn._xlws.FILTER(CONCATENATE(RAW_DATA!$A:$A,RAW_DATA!$B:$B,RAW_DATA!$C:$C),1),$A3)*(RAW_DATA!$T:$T=1)))/$B3),"",SUM(_xlfn._xlws.FILTER(RAW_DATA!K:K,EXACT(_xlfn._xlws.FILTER(CONCATENATE(RAW_DATA!$A:$A,RAW_DATA!$B:$B,RAW_DATA!$C:$C),1),$A3)*(RAW_DATA!$T:$T=1)))/$B3)} | S3: {=IF(ISERR(SUM(_xlfn._xlws.FILTER(RAW_DATA!L:L,EXACT(_xlfn._xlws.FILTER(CONCATENATE(RAW_DATA!$A:$A,RAW_DATA!$B:$B,RAW_DATA!$C:$C),1),$A3)*(RAW_DATA!$T:$T=1)))/$B3),"",SUM(_xlfn._xlws.FILTER(RAW_DATA!L:L,EXACT(_xlfn._xlws.FILTER(CONCATENATE(RAW_DATA!$A:$A,RAW_DATA!$B:$B,RAW_DATA!$C:$C),1),$A3)*(RAW_DATA!$T:$T=1)))/$B3)} | T3: {=IF(ISERR(SUM(_xlfn._xlws.FILTER(RAW_DATA!M:M,EXACT(_xlfn._xlws.FILTER(CONCATENATE(RAW_DATA!$A:$A,RAW_DATA!$B:$B,RAW_DATA!$C:$C),1),$A3)*(RAW_DATA!$V:$V=1)))/$D3),"",SUM(_xlfn._xlws.FILTER(RAW_DATA!M:M,EXACT(_xlfn._xlws.FILTER(CONCATENATE(RAW_DATA!$A:$A,RAW_DATA!$B:$B,RAW_DATA!$C:$C),1),$A3)*(RAW_DATA!$V:$V=1)))/$D3)} -> 0.83511111 | U3: {=IF(ISERR(SUM(_xlfn._xlws.FILTER(RAW_DATA!N:N,EXACT(_xlfn._xlws.FILTER(CONCATENATE(RAW_DATA!$A:$A,RAW_DATA!$B:$B,RAW_DATA!$C:$C),1),$A3)*(RAW_DATA!$V:$V=1)))/$D3),"",SUM(_xlfn._xlws.FILTER(RAW_DATA!N:N,EXACT(_xlfn._xlws.FILTER(CONCATENATE(RAW_DATA!$A:$A,RAW_DATA!$B:$B,RAW_DATA!$C:$C),1),$A3)*(RAW_DATA!$V:$V=1)))/$D3)} -> 1.5622222 | V3: {=IF(ISERR(SUM(_xlfn._xlws.FILTER(RAW_DATA!O:O,EXACT(_xlfn._xlws.FILTER(CONCATENATE(RAW_DATA!$A:$A,RAW_DATA!$B:$B,RAW_DATA!$C:$C),1),$A3)*(RAW_DATA!$V:$V=1)))/$D3),"",SUM(_xlfn._xlws.FILTER(RAW_DATA!O:O,EXACT(_xlfn._xlws.FILTER(CONCATENATE(RAW_DATA!$A:$A,RAW_DATA!$B:$B,RAW_DATA!$C:$C),1),$A3)*(RAW_DATA!$V:$V=1)))/$D3)} -> -1.8669778 | W3: {=IF(ISERR(SUM(_xlfn._xlws.FILTER(RAW_DATA!P:P,EXACT(_xlfn._xlws.FILTER(CONCATENATE(RAW_DATA!$A:$A,RAW_DATA!$B:$B,RAW_DATA!$C:$C),1),$A3)*(RAW_DATA!$V:$V=1)))/$D3),"",SUM(_xlfn._xlws.FILTER(RAW_DATA!P:P,EXACT(_xlfn._xlws.FILTER(CONCATENATE(RAW_DATA!$A:$A,RAW_DATA!$B:$B,RAW_DATA!$C:$C),1),$A3)*(RAW_DATA!$V:$V=1)))/$D3)} -> 1.258 | X3: {=IF(ISERR(SUM(_xlfn._xlws.FILTER(RAW_DATA!Q:Q,EXACT(_xlfn._xlws.FILTER(CONCATENATE(RAW_DATA!$A:$A,RAW_DATA!$B:$B,RAW_DATA!$C:$C),1),$A3)*(RAW_DATA!$V:$V=1)))/$D3),"",SUM(_xlfn._xlws.FILTER(RAW_DATA!Q:Q,EXACT(_xlfn._xlws.FILTER(CONCATENATE(RAW_DATA!$A:$A,RAW_DATA!$B:$B,RAW_DATA!$C:$C),1),$A3)*(RAW_DATA!$V:$V=1)))/$D3)} -> 5.2823889 | Y3: {=IF(ISERR(SUM(_xlfn._xlws.FILTER(RAW_DATA!R:R,EXACT(_xlfn._xlws.FILTER(CONCATENATE(RAW_DATA!$A:$A,RAW_DATA!$B:$B,RAW_DATA!$C:$C),1),$A3)*(RAW_DATA!$V:$V=1)))/$D3),"",SUM(_xlfn._xlws.FILTER(RAW_DATA!R:R,EXACT(_xlfn._xlws.FILTER(CONCATENATE(RAW_DATA!$A:$A,RAW_DATA!$B:$B,RAW_DATA!$C:$C),1),$A3)*(RAW_DATA!$V:$V=1)))/$D3)} -> -0.31688889 | Z3: {=IF(ISERR(SUM(_xlfn._xlws.FILTER(RAW_DATA!S:S,EXACT(_xlfn._xlws.FILTER(CONCATENATE(RAW_DATA!$A:$A,RAW_DATA!$B:$B,RAW_DATA!$C:$C),1),$A3)*(RAW_DATA!$V:$V=1)))/$D3),"",SUM(_xlfn._xlws.FILTER(RAW_DATA!S:S,EXACT(_xlfn._xlws.FILTER(CONCATENATE(RAW_DATA!$A:$A,RAW_DATA!$B:$B,RAW_DATA!$C:$C),1),$A3)*(RAW_DATA!$V:$V=1)))/$D3)} -> 0
A4: Control5AJDPPCSBattery4_8_CONV_STEP | B4: {=IF(ISERR(SUM(_xlfn._xlws.FILTER(RAW_DATA!$T:$T,EXACT(_xlfn._xlws.FILTER(CONCATENATE(RAW_DATA!$A:$A,RAW_DATA!$B:$B,RAW_DATA!$C:$C),1),$A4)))),"",SUM(_xlfn._xlws.FILTER(RAW_DATA!$T:$T,EXACT(_xlfn._xlws.FILTER(CONCATENATE(RAW_DATA!$A:$A,RAW_DATA!$B:$B,RAW_DATA!$C:$C),1),$A4))))} -> 0 | C4: {=IF(ISERR(SUM(_xlfn._xlws.FILTER(RAW_DATA!$U:$U,EXACT(_xlfn._xlws.FILTER(CONCATENATE(RAW_DATA!$A:$A,RAW_DATA!$B:$B,RAW_DATA!$C:$C),1),$A4)))),"",SUM(_xlfn._xlws.FILTER(RAW_DATA!$U:$U,EXACT(_xlfn._xlws.FILTER(CONCATENATE(RAW_DATA!$A:$A,RAW_DATA!$B:$B,RAW_DATA!$C:$C),1),$A4))))} -> 0 | D4: {=IF(ISERR(SUM(_xlfn._xlws.FILTER(RAW_DATA!$V:$V,EXACT(_xlfn._xlws.FILTER(CONCATENATE(RAW_DATA!$A:$A,RAW_DATA!$B:$B,RAW_DATA!$C:$C),1),$A4)))),"",SUM(_xlfn._xlws.FILTER(RAW_DATA!$V:$V,EXACT(_xlfn._xlws.FILTER(CONCATENATE(RAW_DATA!$A:$A,RAW_DATA!$B:$B,RAW_DATA!$C:$C),1),$A4))))} -> 6 | E4: {=IF(ISERR(SUM(_xlfn._xlws.FILTER(RAW_DATA!$X:$X,EXACT(_xlfn._xlws.FILTER(CONCATENATE(RAW_DATA!$A:$A,RAW_DATA!$B:$B,RAW_DATA!$C:$C),1),$A4)*(RAW_DATA!$T:$T=1)))/$B4),"",SUM(_xlfn._xlws.FILTER(RAW_DATA!$X:$X,EXACT(_xlfn._xlws.FILTER(CONCATENATE(RAW_DATA!$A:$A,RAW_DATA!$B:$B,RAW_DATA!$C:$C),1),$A4)*(RAW_DATA!$T:$T=1)))/$B4)} | F4: {=IF(ISERR(SUM(_xlfn._xlws.FILTER(RAW_DATA!$Y:$Y,EXACT(_xlfn._xlws.FILTER(CONCATENATE(RAW_DATA!$A:$A,RAW_DATA!$B:$B,RAW_DATA!$C:$C),1),$A4)*(RAW_DATA!$U:$U=1)))/$C4),"",SUM(_xlfn._xlws.FILTER(RAW_DATA!$Y:$Y,EXACT(_xlfn._xlws.FILTER(CONCATENATE(RAW_DATA!$A:$A,RAW_DATA!$B:$B,RAW_DATA!$C:$C),1),$A4)*(RAW_DATA!$U:$U=1)))/$C4)} | G4: {=IF(ISERR(SUM(_xlfn._xlws.FILTER(RAW_DATA!$Z:$Z,EXACT(_xlfn._xlws.FILTER(CONCATENATE(RAW_DATA!$A:$A,RAW_DATA!$B:$B,RAW_DATA!$C:$C),1),$A4)*(RAW_DATA!$V:$V=1)))/$D4),"",SUM(_xlfn._xlws.FILTER(RAW_DATA!$Z:$Z,EXACT(_xlfn._xlws.FILTER(CONCATENATE(RAW_DATA!$A:$A,RAW_DATA!$B:$B,RAW_DATA!$C:$C),1),$A4)*(RAW_DATA!$V:$V=1)))/$D4)} -> 20.192483 | H4: {=IF(ISERR(SUM(_xlfn._xlws.FILTER(RAW_DATA!$E:$E,EXACT(_xlfn._xlws.FILTER(CONCATENATE(RAW_DATA!$A:$A,RAW_DATA!$B:$B,RAW_DATA!$C:$C),1),$A4)*(RAW_DATA!T:T=1)))/$B4),"",SUM(_xlfn._xlws.FILTER(RAW_DATA!$E:$E,EXACT(_xlfn._xlws.FILTER(CONCATENATE(RAW_DATA!$A:$A,RAW_DATA!$B:$B,RAW_DATA!$C:$C),1),$A4)*(RAW_DATA!T:T=1)))/$B4)} | I4: {=IF(ISERR(SUM(_xlfn._xlws.FILTER(RAW_DATA!$E:$E,EXACT(_xlfn._xlws.FILTER(CONCATENATE(RAW_DATA!$A:$A,RAW_DATA!$B:$B,RAW_DATA!$C:$C),1),$A4)*(RAW_DATA!U:U=1)))/$C4),"",SUM(_xlfn._xlws.FILTER(RAW_DATA!$E:$E,EXACT(_xlfn._xlws.FILTER(CONCATENATE(RAW_DATA!$A:$A,RAW_DATA!$B:$B,RAW_DATA!$C:$C),1),$A4)*(RAW_DATA!U:U=1)))/$C4)} | J4: {=IF(ISERR(SUM(_xlfn._xlws.FILTER(RAW_DATA!$E:$E,EXACT(_xlfn._xlws.FILTER(CONCATENATE(RAW_DATA!$A:$A,RAW_DATA!$B:$B,RAW_DATA!$C:$C),1),$A4)*(RAW_DATA!V:V=1)))/$D4),"",SUM(_xlfn._xlws.FILTER(RAW_DATA!$E:$E,EXACT(_xlfn._xlws.FILTER(CONCATENATE(RAW_DATA!$A:$A,RAW_DATA!$B:$B,RAW_DATA!$C:$C),1),$A4)*(RAW_DATA!V:V=1)))/$D4)} -> 0 | K4: {=IF(ISERR(SUM(_xlfn._xlws.FILTER(RAW_DATA!$F:$F,EXACT(_xlfn._xlws.FILTER(CONCATENATE(RAW_DATA!$A:$A,RAW_DATA!$B:$B,RAW_DATA!$C:$C),1),$A4)*(RAW_DATA!T:T=1)))/$B4),"",SUM(_xlfn._xlws.FILTER(RAW_DATA!$F:$F,EXACT(_xlfn._xlws.FILTER(CONCATENATE(RAW_DATA!$A:$A,RAW_DATA!$B:$B,RAW_DATA!$C:$C),1),$A4)*(RAW_DATA!T:T=1)))/$B4)} | L4: {=IF(ISERR(SUM(_xlfn._xlws.FILTER(RAW_DATA!$F:$F,EXACT(_xlfn._xlws.FILTER(CONCATENATE(RAW_DATA!$A:$A,RAW_DATA!$B:$B,RAW_DATA!$C:$C),1),$A4)*(RAW_DATA!U:U=1)))/$C4),"",SUM(_xlfn._xlws.FILTER(RAW_DATA!$F:$F,EXACT(_xlfn._xlws.FILTER(CONCATENATE(RAW_DATA!$A:$A,RAW_DATA!$B:$B,RAW_DATA!$C:$C),1),$A4)*(RAW_DATA!U:U=1)))/$C4)} | M4: {=IF(ISERR(SUM(_xlfn._xlws.FILTER(RAW_DATA!$F:$F,EXACT(_xlfn._xlws.FILTER(CONCATENATE(RAW_DATA!$A:$A,RAW_DATA!$B:$B,RAW_DATA!$C:$C),1),$A4)*(RAW_DATA!V:V=1)))/$D4),"",SUM(_xlfn._xlws.FILTER(RAW_DATA!$F:$F,EXACT(_xlfn._xlws.FILTER(CONCATENATE(RAW_DATA!$A:$A,RAW_DATA!$B:$B,RAW_DATA!$C:$C),1),$A4)*(RAW_DATA!V:V=1)))/$D4)} -> 0.33333333 | N4: {=IF(ISERR(SUM(_xlfn._xlws.FILTER(RAW_DATA!G:G,EXACT(_xlfn._xlws.FILTER(CONCATENATE(RAW_DATA!$A:$A,RAW_DATA!$B:$B,RAW_DATA!$C:$C),1),$A4)*(RAW_DATA!$T:$T=1)))/$B4),"",SUM(_xlfn._xlws.FILTER(RAW_DATA!G:G,EXACT(_xlfn._xlws.FILTER(CONCATENATE(RAW_DATA!$A:$A,RAW_DATA!$B:$B,RAW_DATA!$C:$C),1),$A4)*(RAW_DATA!$T:$T=1)))/$B4)} | O4: {=IF(ISERR(SUM(_xlfn._xlws.FILTER(RAW_DATA!H:H,EXACT(_xlfn._xlws.FILTER(CONCATENATE(RAW_DATA!$A:$A,RAW_DATA!$B:$B,RAW_DATA!$C:$C),1),$A4)*(RAW_DATA!$T:$T=1)))/$B4),"",SUM(_xlfn._xlws.FILTER(RAW_DATA!H:H,EXACT(_xlfn._xlws.FILTER(CONCATENATE(RAW_DATA!$A:$A,RAW_DATA!$B:$B,RAW_DATA!$C:$C),1),$A4)*(RAW_DATA!$T:$T=1)))/$B4)} | P4: {=IF(ISERR(SUM(_xlfn._xlws.FILTER(RAW_DATA!I:I,EXACT(_xlfn._xlws.FILTER(CONCATENATE(RAW_DATA!$A:$A,RAW_DATA!$B:$B,RAW_DATA!$C:$C),1),$A4)*(RAW_DATA!$T:$T=1)))/$B4),"",SUM(_xlfn._xlws.FILTER(RAW_DATA!I:I,EXACT(_xlfn._xlws.FILTER(CONCATENATE(RAW_DATA!$A:$A,RAW_DATA!$B:$B,RAW_DATA!$C:$C),1),$A4)*(RAW_DATA!$T:$T=1)))/$B4)} | Q4: {=IF(ISERR(SUM(_xlfn._xlws.FILTER(RAW_DATA!J:J,EXACT(_xlfn._xlws.FILTER(CONCATENATE(RAW_DATA!$A:$A,RAW_DATA!$B:$B,RAW_DATA!$C:$C),1),$A4)*(RAW_DATA!$T:$T=1)))/$B4),"",SUM(_xlfn._xlws.FILTER(RAW_DATA!J:J,EXACT(_xlfn._xlws.FILTER(CONCATENATE(RAW_DATA!$A:$A,RAW_DATA!$B:$B,RAW_DATA!$C:$C),1),$A4)*(RAW_DATA!$T:$T=1)))/$B4)} | R4: {=IF(ISERR(SUM(_xlfn._xlws.FILTER(RAW_DATA!K:K,EXACT(_xlfn._xlws.FILTER(CONCATENATE(RAW_DATA!$A:$A,RAW_DATA!$B:$B,RAW_DATA!$C:$C),1),$A4)*(RAW_DATA!$T:$T=1)))/$B4),"",SUM(_xlfn._xlws.FILTER(RAW_DATA!K:K,EXACT(_xlfn._xlws.FILTER(CONCATENATE(RAW_DATA!$A:$A,RAW_DATA!$B:$B,RAW_DATA!$C:$C),1),$A4)*(RAW_DATA!$T:$T=1)))/$B4)} | S4: {=IF(ISERR(SUM(_xlfn._xlws.FILTER(RAW_DATA!L:L,EXACT(_xlfn._xlws.FILTER(CONCATENATE(RAW_DATA!$A:$A,RAW_DATA!$B:$B,RAW_DATA!$C:$C),1),$A4)*(RAW_DATA!$T:$T=1)))/$B4),"",SUM(_xlfn._xlws.FILTER(RAW_DATA!L:L,EXACT(_xlfn._xlws.FILTER(CONCATENATE(RAW_DATA!$A:$A,RAW_DATA!$B:$B,RAW_DATA!$C:$C),1),$A4)*(RAW_DATA!$T:$T=1)))/$B4)} | T4: {=IF(ISERR(SUM(_xlfn._xlws.FILTER(RAW_DATA!M:M,EXACT(_xlfn._xlws.FILTER(CONCATENATE(RAW_DATA!$A:$A,RAW_DATA!$B:$B,RAW_DATA!$C:$C),1),$A4)*(RAW_DATA!$V:$V=1)))/$D4),"",SUM(_xlfn._xlws.FILTER(RAW_DATA!M:M,EXACT(_xlfn._xlws.FILTER(CONCATENATE(RAW_DATA!$A:$A,RAW_DATA!$B:$B,RAW_DATA!$C:$C),1),$A4)*(RAW_DATA!$V:$V=1)))/$D4)} -> 0.77933333 | U4: {=IF(ISERR(SUM(_xlfn._xlws.FILTER(RAW_DATA!N:N,EXACT(_xlfn._xlws.FILTER(CONCATENATE(RAW_DATA!$A:$A,RAW_DATA!$B:$B,RAW_DATA!$C:$C),1),$A4)*(RAW_DATA!$V:$V=1)))/$D4),"",SUM(_xlfn._xlws.FILTER(RAW_DATA!N:N,EXACT(_xlfn._xlws.FILTER(CONCATENATE(RAW_DATA!$A:$A,RAW_DATA!$B:$B,RAW_DATA!$C:$C),1),$A4)*(RAW_DATA!$V:$V=1)))/$D4)} -> 1.4746667 | V4: {=IF(ISERR(SUM(_xlfn._xlws.FILTER(RAW_DATA!O:O,EXACT(_xlfn._xlws.FILTER(CONCATENATE(RAW_DATA!$A:$A,RAW_DATA!$B:$B,RAW_DATA!$C:$C),1),$A4)*(RAW_DATA!$V:$V=1)))/$D4),"",SUM(_xlfn._xlws.FILTER(RAW_DATA!O:O,EXACT(_xlfn._xlws.FILTER(CONCATENATE(RAW_DATA!$A:$A,RAW_DATA!$B:$B,RAW_DATA!$C:$C),1),$A4)*(RAW_DATA!$V:$V=1)))/$D4)} -> -2.64495 | W4: {=IF(ISERR(SUM(_xlfn._xlws.FILTER(RAW_DATA!P:P,EXACT(_xlfn._xlws.FILTER(CONCATENATE(RAW_DATA!$A:$A,RAW_DATA!$B:$B,RAW_DATA!$C:$C),1),$A4)*(RAW_DATA!$V:$V=1)))/$D4),"",SUM(_xlfn._xlws.FILTER(RAW_DATA!P:P,EXACT(_xlfn._xlws.FILTER(CONCATENATE(RAW_DATA!$A:$A,RAW_DATA!$B:$B,RAW_DATA!$C:$C),1),$A4)*(RAW_DATA!$V:$V=1)))/$D4)} -> 1.1086667 | X4: {=IF(ISERR(SUM(_xlfn._xlws.FILTER(RAW_DATA!Q:Q,EXACT(_xlfn._xlws.FILTER(CONCATENATE(RAW_DATA!$A:$A,RAW_DATA!$B:$B,RAW_DATA!$C:$C),1),$A4)*(RAW_DATA!$V:$V=1)))/$D4),"",SUM(_xlfn._xlws.FILTER(RAW_DATA!Q:Q,EXACT(_xlfn._xlws.FILTER(CONCATENATE(RAW_DATA!$A:$A,RAW_DATA!$B:$B,RAW_DATA!$C:$C),1),$A4)*(RAW_DATA!$V:$V=1)))/$D4)} -> 7.9088167 | Y4: {=IF(ISERR(SUM(_xlfn._xlws.FILTER(RAW_DATA!R:R,EXACT(_xlfn._xlws.FILTER(CONCATENATE(RAW_DATA!$A:$A,RAW_DATA!$B:$B,RAW_DATA!$C:$C),1),$A4)*(RAW_DATA!$V:$V=1)))/$D4),"",SUM(_xlfn._xlws.FILTER(RAW_DATA!R:R,EXACT(_xlfn._xlws.FILTER(CONCATENATE(RAW_DATA!$A:$A,RAW_DATA!$B:$B,RAW_DATA!$C:$C),1),$A4)*(RAW_DATA!$V:$V=1)))/$D4)} -> -0.71133333 | Z4: {=IF(ISERR(SUM(_xlfn._xlws.FILTER(RAW_DATA!S:S,EXACT(_xlfn._xlws.FILTER(CONCATENATE(RAW_DATA!$A:$A,RAW_DATA!$B:$B,RAW_DATA!$C:$C),1),$A4)*(RAW_DATA!$V:$V=1)))/$D4),"",SUM(_xlfn._xlws.FILTER(RAW_DATA!S:S,EXACT(_xlfn._xlws.FILTER(CONCATENATE(RAW_DATA!$A:$A,RAW_DATA!$B:$B,RAW_DATA!$C:$C),1),$A4)*(RAW_DATA!$V:$V=1)))/$D4)} -> 0
A5: Control6JPMPPCSBattery4_8_CONV_STEP | B5: {=IF(ISERR(SUM(_xlfn._xlws.FILTER(RAW_DATA!$T:$T,EXACT(_xlfn._xlws.FILTER(CONCATENATE(RAW_DATA!$A:$A,RAW_DATA!$B:$B,RAW_DATA!$C:$C),1),$A5)))),"",SUM(_xlfn._xlws.FILTER(RAW_DATA!$T:$T,EXACT(_xlfn._xlws.FILTER(CONCATENATE(RAW_DATA!$A:$A,RAW_DATA!$B:$B,RAW_DATA!$C:$C),1),$A5))))} -> 0 | C5: {=IF(ISERR(SUM(_xlfn._xlws.FILTER(RAW_DATA!$U:$U,EXACT(_xlfn._xlws.FILTER(CONCATENATE(RAW_DATA!$A:$A,RAW_DATA!$B:$B,RAW_DATA!$C:$C),1),$A5)))),"",SUM(_xlfn._xlws.FILTER(RAW_DATA!$U:$U,EXACT(_xlfn._xlws.FILTER(CONCATENATE(RAW_DATA!$A:$A,RAW_DATA!$B:$B,RAW_DATA!$C:$C),1),$A5))))} -> 0 | D5: {=IF(ISERR(SUM(_xlfn._xlws.FILTER(RAW_DATA!$V:$V,EXACT(_xlfn._xlws.FILTER(CONCATENATE(RAW_DATA!$A:$A,RAW_DATA!$B:$B,RAW_DATA!$C:$C),1),$A5)))),"",SUM(_xlfn._xlws.FILTER(RAW_DATA!$V:$V,EXACT(_xlfn._xlws.FILTER(CONCATENATE(RAW_DATA!$A:$A,RAW_DATA!$B:$B,RAW_DATA!$C:$C),1),$A5))))} -> 8 | E5: {=IF(ISERR(SUM(_xlfn._xlws.FILTER(RAW_DATA!$X:$X,EXACT(_xlfn._xlws.FILTER(CONCATENATE(RAW_DATA!$A:$A,RAW_DATA!$B:$B,RAW_DATA!$C:$C),1),$A5)*(RAW_DATA!$T:$T=1)))/$B5),"",SUM(_xlfn._xlws.FILTER(RAW_DATA!$X:$X,EXACT(_xlfn._xlws.FILTER(CONCATENATE(RAW_DATA!$A:$A,RAW_DATA!$B:$B,RAW_DATA!$C:$C),1),$A5)*(RAW_DATA!$T:$T=1)))/$B5)} | F5: {=IF(ISERR(SUM(_xlfn._xlws.FILTER(RAW_DATA!$Y:$Y,EXACT(_xlfn._xlws.FILTER(CONCATENATE(RAW_DATA!$A:$A,RAW_DATA!$B:$B,RAW_DATA!$C:$C),1),$A5)*(RAW_DATA!$U:$U=1)))/$C5),"",SUM(_xlfn._xlws.FILTER(RAW_DATA!$Y:$Y,EXACT(_xlfn._xlws.FILTER(CONCATENATE(RAW_DATA!$A:$A,RAW_DATA!$B:$B,RAW_DATA!$C:$C),1),$A5)*(RAW_DATA!$U:$U=1)))/$C5)} | G5: {=IF(ISERR(SUM(_xlfn._xlws.FILTER(RAW_DATA!$Z:$Z,EXACT(_xlfn._xlws.FILTER(CONCATENATE(RAW_DATA!$A:$A,RAW_DATA!$B:$B,RAW_DATA!$C:$C),1),$A5)*(RAW_DATA!$V:$V=1)))/$D5),"",SUM(_xlfn._xlws.FILTER(RAW_DATA!$Z:$Z,EXACT(_xlfn._xlws.FILTER(CONCATENATE(RAW_DATA!$A:$A,RAW_DATA!$B:$B,RAW_DATA!$C:$C),1),$A5)*(RAW_DATA!$V:$V=1)))/$D5)} -> 20.192483 | H5: {=IF(ISERR(SUM(_xlfn._xlws.FILTER(RAW_DATA!$E:$E,EXACT(_xlfn._xlws.FILTER(CONCATENATE(RAW_DATA!$A:$A,RAW_DATA!$B:$B,RAW_DATA!$C:$C),1),$A5)*(RAW_DATA!T:T=1)))/$B5),"",SUM(_xlfn._xlws.FILTER(RAW_DATA!$E:$E,EXACT(_xlfn._xlws.FILTER(CONCATENATE(RAW_DATA!$A:$A,RAW_DATA!$B:$B,RAW_DATA!$C:$C),1),$A5)*(RAW_DATA!T:T=1)))/$B5)} | I5: {=IF(ISERR(SUM(_xlfn._xlws.FILTER(RAW_DATA!$E:$E,EXACT(_xlfn._xlws.FILTER(CONCATENATE(RAW_DATA!$A:$A,RAW_DATA!$B:$B,RAW_DATA!$C:$C),1),$A5)*(RAW_DATA!U:U=1)))/$C5),"",SUM(_xlfn._xlws.FILTER(RAW_DATA!$E:$E,EXACT(_xlfn._xlws.FILTER(CONCATENATE(RAW_DATA!$A:$A,RAW_DATA!$B:$B,RAW_DATA!$C:$C),1),$A5)*(RAW_DATA!U:U=1)))/$C5)} | J5: {=IF(ISERR(SUM(_xlfn._xlws.FILTER(RAW_DATA!$E:$E,EXACT(_xlfn._xlws.FILTER(CONCATENATE(RAW_DATA!$A:$A,RAW_DATA!$B:$B,RAW_DATA!$C:$C),1),$A5)*(RAW_DATA!V:V=1)))/$D5),"",SUM(_xlfn._xlws.FILTER(RAW_DATA!$E:$E,EXACT(_xlfn._xlws.FILTER(CONCATENATE(RAW_DATA!$A:$A,RAW_DATA!$B:$B,RAW_DATA!$C:$C),1),$A5)*(RAW_DATA!V:V=1)))/$D5)} -> 0 | K5: {=IF(ISERR(SUM(_xlfn._xlws.FILTER(RAW_DATA!$F:$F,EXACT(_xlfn._xlws.FILTER(CONCATENATE(RAW_DATA!$A:$A,RAW_DATA!$B:$B,RAW_DATA!$C:$C),1),$A5)*(RAW_DATA!T:T=1)))/$B5),"",SUM(_xlfn._xlws.FILTER(RAW_DATA!$F:$F,EXACT(_xlfn._xlws.FILTER(CONCATENATE(RAW_DATA!$A:$A,RAW_DATA!$B:$B,RAW_DATA!$C:$C),1),$A5)*(RAW_DATA!T:T=1)))/$B5)} | L5: {=IF(ISERR(SUM(_xlfn._xlws.FILTER(RAW_DATA!$F:$F,EXACT(_xlfn._xlws.FILTER(CONCATENATE(RAW_DATA!$A:$A,RAW_DATA!$B:$B,RAW_DATA!$C:$C),1),$A5)*(RAW_DATA!U:U=1)))/$C5),"",SUM(_xlfn._xlws.FILTER(RAW_DATA!$F:$F,EXACT(_xlfn._xlws.FILTER(CONCATENATE(RAW_DATA!$A:$A,RAW_DATA!$B:$B,RAW_DATA!$C:$C),1),$A5)*(RAW_DATA!U:U=1)))/$C5)} | M5: {=IF(ISERR(SUM(_xlfn._xlws.FILTER(RAW_DATA!$F:$F,EXACT(_xlfn._xlws.FILTER(CONCATENATE(RAW_DATA!$A:$A,RAW_DATA!$B:$B,RAW_DATA!$C:$C),1),$A5)*(RAW_DATA!V:V=1)))/$D5),"",SUM(_xlfn._xlws.FILTER(RAW_DATA!$F:$F,EXACT(_xlfn._xlws.FILTER(CONCATENATE(RAW_DATA!$A:$A,RAW_DATA!$B:$B,RAW_DATA!$C:$C),1),$A5)*(RAW_DATA!V:V=1)))/$D5)} -> 0.125 | N5: {=IF(ISERR(SUM(_xlfn._xlws.FILTER(RAW_DATA!G:G,EXACT(_xlfn._xlws.FILTER(CONCATENATE(RAW_DATA!$A:$A,RAW_DATA!$B:$B,RAW_DATA!$C:$C),1),$A5)*(RAW_DATA!$T:$T=1)))/$B5),"",SUM(_xlfn._xlws.FILTER(RAW_DATA!G:G,EXACT(_xlfn._xlws.FILTER(CONCATENATE(RAW_DATA!$A:$A,RAW_DATA!$B:$B,RAW_DATA!$C:$C),1),$A5)*(RAW_DATA!$T:$T=1)))/$B5)} | O5: {=IF(ISERR(SUM(_xlfn._xlws.FILTER(RAW_DATA!H:H,EXACT(_xlfn._xlws.FILTER(CONCATENATE(RAW_DATA!$A:$A,RAW_DATA!$B:$B,RAW_DATA!$C:$C),1),$A5)*(RAW_DATA!$T:$T=1)))/$B5),"",SUM(_xlfn._xlws.FILTER(RAW_DATA!H:H,EXACT(_xlfn._xlws.FILTER(CONCATENATE(RAW_DATA!$A:$A,RAW_DATA!$B:$B,RAW_DATA!$C:$C),1),$A5)*(RAW_DATA!$T:$T=1)))/$B5)} | P5: {=IF(ISERR(SUM(_xlfn._xlws.FILTER(RAW_DATA!I:I,EXACT(_xlfn._xlws.FILTER(CONCATENATE(RAW_DATA!$A:$A,RAW_DATA!$B:$B,RAW_DATA!$C:$C),1),$A5)*(RAW_DATA!$T:$T=1)))/$B5),"",SUM(_xlfn._xlws.FILTER(RAW_DATA!I:I,EXACT(_xlfn._xlws.FILTER(CONCATENATE(RAW_DATA!$A:$A,RAW_DATA!$B:$B,RAW_DATA!$C:$C),1),$A5)*(RAW_DATA!$T:$T=1)))/$B5)} | Q5: {=IF(ISERR(SUM(_xlfn._xlws.FILTER(RAW_DATA!J:J,EXACT(_xlfn._xlws.FILTER(CONCATENATE(RAW_DATA!$A:$A,RAW_DATA!$B:$B,RAW_DATA!$C:$C),1),$A5)*(RAW_DATA!$T:$T=1)))/$B5),"",SUM(_xlfn._xlws.FILTER(RAW_DATA!J:J,EXACT(_xlfn._xlws.FILTER(CONCATENATE(RAW_DATA!$A:$A,RAW_DATA!$B:$B,RAW_DATA!$C:$C),1),$A5)*(RAW_DATA!$T:$T=1)))/$B5)} | R5: {=IF(ISERR(SUM(_xlfn._xlws.FILTER(RAW_DATA!K:K,EXACT(_xlfn._xlws.FILTER(CONCATENATE(RAW_DATA!$A:$A,RAW_DATA!$B:$B,RAW_DATA!$C:$C),1),$A5)*(RAW_DATA!$T:$T=1)))/$B5),"",SUM(_xlfn._xlws.FILTER(RAW_DATA!K:K,EXACT(_xlfn._xlws.FILTER(CONCATENATE(RAW_DATA!$A:$A,RAW_DATA!$B:$B,RAW_DATA!$C:$C),1),$A5)*(RAW_DATA!$T:$T=1)))/$B5)} | S5: {=IF(ISERR(SUM(_xlfn._xlws.FILTER(RAW_DATA!L:L,EXACT(_xlfn._xlws.FILTER(CONCATENATE(RAW_DATA!$A:$A,RAW_DATA!$B:$B,RAW_DATA!$C:$C),1),$A5)*(RAW_DATA!$T:$T=1)))/$B5),"",SUM(_xlfn._xlws.FILTER(RAW_DATA!L:L,EXACT(_xlfn._xlws.FILTER(CONCATENATE(RAW_DATA!$A:$A,RAW_DATA!$B:$B,RAW_DATA!$C:$C),1),$A5)*(RAW_DATA!$T:$T=1)))/$B5)} | T5: {=IF(ISERR(SUM(_xlfn._xlws.FILTER(RAW_DATA!M:M,EXACT(_xlfn._xlws.FILTER(CONCATENATE(RAW_DATA!$A:$A,RAW_DATA!$B:$B,RAW_DATA!$C:$C),1),$A5)*(RAW_DATA!$V:$V=1)))/$D5),"",SUM(_xlfn._xlws.FILTER(RAW_DATA!M:M,EXACT(_xlfn._xlws.FILTER(CONCATENATE(RAW_DATA!$A:$A,RAW_DATA!$B:$B,RAW_DATA!$C:$C),1),$A5)*(RAW_DATA!$V:$V=1)))/$D5)} -> 0.809 | U5: {=IF(ISERR(SUM(_xlfn._xlws.FILTER(RAW_DATA!N:N,EXACT(_xlfn._xlws.FILTER(CONCATENATE(RAW_DATA!$A:$A,RAW_DATA!$B:$B,RAW_DATA!$C:$C),1),$A5)*(RAW_DATA!$V:$V=1)))/$D5),"",SUM(_xlfn._xlws.FILTER(RAW_DATA!N:N,EXACT(_xlfn._xlws.FILTER(CONCATENATE(RAW_DATA!$A:$A,RAW_DATA!$B:$B,RAW_DATA!$C:$C),1),$A5)*(RAW_DATA!$V:$V=1)))/$D5)} -> 1.40725 | V5: {=IF(ISERR(SUM(_xlfn._xlws.FILTER(RAW_DATA!O:O,EXACT(_xlfn._xlws.FILTER(CONCATENATE(RAW_DATA!$A:$A,RAW_DATA!$B:$B,RAW_DATA!$C:$C),1),$A5)*(RAW_DATA!$V:$V=1)))/$D5),"",SUM(_xlfn._xlws.FILTER(RAW_DATA!O:O,EXACT(_xlfn._xlws.FILTER(CONCATENATE(RAW_DATA!$A:$A,RAW_DATA!$B:$B,RAW_DATA!$C:$C),1),$A5)*(RAW_DATA!$V:$V=1)))/$D5)} -> -2.4813 | W5: {=IF(ISERR(SUM(_xlfn._xlws.FILTER(RAW_DATA!P:P,EXACT(_xlfn._xlws.FILTER(CONCATENATE(RAW_DATA!$A:$A,RAW_DATA!$B:$B,RAW_DATA!$C:$C),1),$A5)*(RAW_DATA!$V:$V=1)))/$D5),"",SUM(_xlfn._xlws.FILTER(RAW_DATA!P:P,EXACT(_xlfn._xlws.FILTER(CONCATENATE(RAW_DATA!$A:$A,RAW_DATA!$B:$B,RAW_DATA!$C:$C),1),$A5)*(RAW_DATA!$V:$V=1)))/$D5)} -> 1.13925 | X5: {=IF(ISERR(SUM(_xlfn._xlws.FILTER(RAW_DATA!Q:Q,EXACT(_xlfn._xlws.FILTER(CONCATENATE(RAW_DATA!$A:$A,RAW_DATA!$B:$B,RAW_DATA!$C:$C),1),$A5)*(RAW_DATA!$V:$V=1)))/$D5),"",SUM(_xlfn._xlws.FILTER(RAW_DATA!Q:Q,EXACT(_xlfn._xlws.FILTER(CONCATENATE(RAW_DATA!$A:$A,RAW_DATA!$B:$B,RAW_DATA!$C:$C),1),$A5)*(RAW_DATA!$V:$V=1)))/$D5)} -> 7.7346 | Y5: {=IF(ISERR(SUM(_xlfn._xlws.FILTER(RAW_DATA!R:R,EXACT(_xlfn._xlws.FILTER(CONCATENATE(RAW_DATA!$A:$A,RAW_DATA!$B:$B,RAW_DATA!$C:$C),1),$A5)*(RAW_DATA!$V:$V=1)))/$D5),"",SUM(_xlfn._xlws.FILTER(RAW_DATA!R:R,EXACT(_xlfn._xlws.FILTER(CONCATENATE(RAW_DATA!$A:$A,RAW_DATA!$B:$B,RAW_DATA!$C:$C),1),$A5)*(RAW_DATA!$V:$V=1)))/$D5)} -> -0.346625 | Z5: {=IF(ISERR(SUM(_xlfn._xlws.FILTER(RAW_DATA!S:S,EXACT(_xlfn._xlws.FILTER(CONCATENATE(RAW_DATA!$A:$A,RAW_DATA!$B:$B,RAW_DATA!$C:$C),1),$A5)*(RAW_DATA!$V:$V=1)))/$D5),"",SUM(_xlfn._xlws.FILTER(RAW_DATA!S:S,EXACT(_xlfn._xlws.FILTER(CONCATENATE(RAW_DATA!$A:$A,RAW_DATA!$B:$B,RAW_DATA!$C:$C),1),$A5)*(RAW_DATA!$V:$V=1)))/$D5)} -> 0
A6: Control7VXRPPCSBattery4_8_CONV_STEP | B6: {=IF(ISERR(SUM(_xlfn._xlws.FILTER(RAW_DATA!$T:$T,EXACT(_xlfn._xlws.FILTER(CONCATENATE(RAW_DATA!$A:$A,RAW_DATA!$B:$B,RAW_DATA!$C:$C),1),$A6)))),"",SUM(_xlfn._xlws.FILTER(RAW_DATA!$T:$T,EXACT(_xlfn._xlws.FILTER(CONCATENATE(RAW_DATA!$A:$A,RAW_DATA!$B:$B,RAW_DATA!$C:$C),1),$A6))))} -> 0 | C6: {=IF(ISERR(SUM(_xlfn._xlws.FILTER(RAW_DATA!$U:$U,EXACT(_xlfn._xlws.FILTER(CONCATENATE(RAW_DATA!$A:$A,RAW_DATA!$B:$B,RAW_DATA!$C:$C),1),$A6)))),"",SUM(_xlfn._xlws.FILTER(RAW_DATA!$U:$U,EXACT(_xlfn._xlws.FILTER(CONCATENATE(RAW_DATA!$A:$A,RAW_DATA!$B:$B,RAW_DATA!$C:$C),1),$A6))))} -> 0 | D6: {=IF(ISERR(SUM(_xlfn._xlws.FILTER(RAW_DATA!$V:$V,EXACT(_xlfn._xlws.FILTER(CONCATENATE(RAW_DATA!$A:$A,RAW_DATA!$B:$B,RAW_DATA!$C:$C),1),$A6)))),"",SUM(_xlfn._xlws.FILTER(RAW_DATA!$V:$V,EXACT(_xlfn._xlws.FILTER(CONCATENATE(RAW_DATA!$A:$A,RAW_DATA!$B:$B,RAW_DATA!$C:$C),1),$A6))))} -> 9 | E6: {=IF(ISERR(SUM(_xlfn._xlws.FILTER(RAW_DATA!$X:$X,EXACT(_xlfn._xlws.FILTER(CONCATENATE(RAW_DATA!$A:$A,RAW_DATA!$B:$B,RAW_DATA!$C:$C),1),$A6)*(RAW_DATA!$T:$T=1)))/$B6),"",SUM(_xlfn._xlws.FILTER(RAW_DATA!$X:$X,EXACT(_xlfn._xlws.FILTER(CONCATENATE(RAW_DATA!$A:$A,RAW_DATA!$B:$B,RAW_DATA!$C:$C),1),$A6)*(RAW_DATA!$T:$T=1)))/$B6)} | F6: {=IF(ISERR(SUM(_xlfn._xlws.FILTER(RAW_DATA!$Y:$Y,EXACT(_xlfn._xlws.FILTER(CONCATENATE(RAW_DATA!$A:$A,RAW_DATA!$B:$B,RAW_DATA!$C:$C),1),$A6)*(RAW_DATA!$U:$U=1)))/$C6),"",SUM(_xlfn._xlws.FILTER(RAW_DATA!$Y:$Y,EXACT(_xlfn._xlws.FILTER(CONCATENATE(RAW_DATA!$A:$A,RAW_DATA!$B:$B,RAW_DATA!$C:$C),1),$A6)*(RAW_DATA!$U:$U=1)))/$C6)} | G6: {=IF(ISERR(SUM(_xlfn._xlws.FILTER(RAW_DATA!$Z:$Z,EXACT(_xlfn._xlws.FILTER(CONCATENATE(RAW_DATA!$A:$A,RAW_DATA!$B:$B,RAW_DATA!$C:$C),1),$A6)*(RAW_DATA!$V:$V=1)))/$D6),"",SUM(_xlfn._xlws.FILTER(RAW_DATA!$Z:$Z,EXACT(_xlfn._xlws.FILTER(CONCATENATE(RAW_DATA!$A:$A,RAW_DATA!$B:$B,RAW_DATA!$C:$C),1),$A6)*(RAW_DATA!$V:$V=1)))/$D6)} -> 20.192483 | H6: {=IF(ISERR(SUM(_xlfn._xlws.FILTER(RAW_DATA!$E:$E,EXACT(_xlfn._xlws.FILTER(CONCATENATE(RAW_DATA!$A:$A,RAW_DATA!$B:$B,RAW_DATA!$C:$C),1),$A6)*(RAW_DATA!T:T=1)))/$B6),"",SUM(_xlfn._xlws.FILTER(RAW_DATA!$E:$E,EXACT(_xlfn._xlws.FILTER(CONCATENATE(RAW_DATA!$A:$A,RAW_DATA!$B:$B,RAW_DATA!$C:$C),1),$A6)*(RAW_DATA!T:T=1)))/$B6)} | I6: {=IF(ISERR(SUM(_xlfn._xlws.FILTER(RAW_DATA!$E:$E,EXACT(_xlfn._xlws.FILTER(CONCATENATE(RAW_DATA!$A:$A,RAW_DATA!$B:$B,RAW_DATA!$C:$C),1),$A6)*(RAW_DATA!U:U=1)))/$C6),"",SUM(_xlfn._xlws.FILTER(RAW_DATA!$E:$E,EXACT(_xlfn._xlws.FILTER(CONCATENATE(RAW_DATA!$A:$A,RAW_DATA!$B:$B,RAW_DATA!$C:$C),1),$A6)*(RAW_DATA!U:U=1)))/$C6)} | J6: {=IF(ISERR(SUM(_xlfn._xlws.FILTER(RAW_DATA!$E:$E,EXACT(_xlfn._xlws.FILTER(CONCATENATE(RAW_DATA!$A:$A,RAW_DATA!$B:$B,RAW_DATA!$C:$C),1),$A6)*(RAW_DATA!V:V=1)))/$D6),"",SUM(_xlfn._xlws.FILTER(RAW_DATA!$E:$E,EXACT(_xlfn._xlws.FILTER(CONCATENATE(RAW_DATA!$A:$A,RAW_DATA!$B:$B,RAW_DATA!$C:$C),1),$A6)*(RAW_DATA!V:V=1)))/$D6)} -> 0 | K6: {=IF(ISERR(SUM(_xlfn._xlws.FILTER(RAW_DATA!$F:$F,EXACT(_xlfn._xlws.FILTER(CONCATENATE(RAW_DATA!$A:$A,RAW_DATA!$B:$B,RAW_DATA!$C:$C),1),$A6)*(RAW_DATA!T:T=1)))/$B6),"",SUM(_xlfn._xlws.FILTER(RAW_DATA!$F:$F,EXACT(_xlfn._xlws.FILTER(CONCATENATE(RAW_DATA!$A:$A,RAW_DATA!$B:$B,RAW_DATA!$C:$C),1),$A6)*(RAW_DATA!T:T=1)))/$B6)} | L6: {=IF(ISERR(SUM(_xlfn._xlws.FILTER(RAW_DATA!$F:$F,EXACT(_xlfn._xlws.FILTER(CONCATENATE(RAW_DATA!$A:$A,RAW_DATA!$B:$B,RAW_DATA!$C:$C),1),$A6)*(RAW_DATA!U:U=1)))/$C6),"",SUM(_xlfn._xlws.FILTER(RAW_DATA!$F:$F,EXACT(_xlfn._xlws.FILTER(CONCATENATE(RAW_DATA!$A:$A,RAW_DATA!$B:$B,RAW_DATA!$C:$C),1),$A6)*(RAW_DATA!U:U=1)))/$C6)} | M6: {=IF(ISERR(SUM(_xlfn._xlws.FILTER(RAW_DATA!$F:$F,EXACT(_xlfn._xlws.FILTER(CONCATENATE(RAW_DATA!$A:$A,RAW_DATA!$B:$B,RAW_DATA!$C:$C),1),$A6)*(RAW_DATA!V:V=1)))/$D6),"",SUM(_xlfn._xlws.FILTER(RAW_DATA!$F:$F,EXACT(_xlfn._xlws.FILTER(CONCATENATE(RAW_DATA!$A:$A,RAW_DATA!$B:$B,RAW_DATA!$C:$C),1),$A6)*(RAW_DATA!V:V=1)))/$D6)} -> 1.6666667 | N6: {=IF(ISERR(SUM(_xlfn._xlws.FILTER(RAW_DATA!G:G,EXACT(_xlfn._xlws.FILTER(CONCATENATE(RAW_DATA!$A:$A,RAW_DATA!$B:$B,RAW_DATA!$C:$C),1),$A6)*(RAW_DATA!$T:$T=1)))/$B6),"",SUM(_xlfn._xlws.FILTER(RAW_DATA!G:G,EXACT(_xlfn._xlws.FILTER(CONCATENATE(RAW_DATA!$A:$A,RAW_DATA!$B:$B,RAW_DATA!$C:$C),1),$A6)*(RAW_DATA!$T:$T=1)))/$B6)} | O6: {=IF(ISERR(SUM(_xlfn._xlws.FILTER(RAW_DATA!H:H,EXACT(_xlfn._xlws.FILTER(CONCATENATE(RAW_DATA!$A:$A,RAW_DATA!$B:$B,RAW_DATA!$C:$C),1),$A6)*(RAW_DATA!$T:$T=1)))/$B6),"",SUM(_xlfn._xlws.FILTER(RAW_DATA!H:H,EXACT(_xlfn._xlws.FILTER(CONCATENATE(RAW_DATA!$A:$A,RAW_DATA!$B:$B,RAW_DATA!$C:$C),1),$A6)*(RAW_DATA!$T:$T=1)))/$B6)} | P6: {=IF(ISERR(SUM(_xlfn._xlws.FILTER(RAW_DATA!I:I,EXACT(_xlfn._xlws.FILTER(CONCATENATE(RAW_DATA!$A:$A,RAW_DATA!$B:$B,RAW_DATA!$C:$C),1),$A6)*(RAW_DATA!$T:$T=1)))/$B6),"",SUM(_xlfn._xlws.FILTER(RAW_DATA!I:I,EXACT(_xlfn._xlws.FILTER(CONCATENATE(RAW_DATA!$A:$A,RAW_DATA!$B:$B,RAW_DATA!$C:$C),1),$A6)*(RAW_DATA!$T:$T=1)))/$B6)} | Q6: {=IF(ISERR(SUM(_xlfn._xlws.FILTER(RAW_DATA!J:J,EXACT(_xlfn._xlws.FILTER(CONCATENATE(RAW_DATA!$A:$A,RAW_DATA!$B:$B,RAW_DATA!$C:$C),1),$A6)*(RAW_DATA!$T:$T=1)))/$B6),"",SUM(_xlfn._xlws.FILTER(RAW_DATA!J:J,EXACT(_xlfn._xlws.FILTER(CONCATENATE(RAW_DATA!$A:$A,RAW_DATA!$B:$B,RAW_DATA!$C:$C),1),$A6)*(RAW_DATA!$T:$T=1)))/$B6)} | R6: {=IF(ISERR(SUM(_xlfn._xlws.FILTER(RAW_DATA!K:K,EXACT(_xlfn._xlws.FILTER(CONCATENATE(RAW_DATA!$A:$A,RAW_DATA!$B:$B,RAW_DATA!$C:$C),1),$A6)*(RAW_DATA!$T:$T=1)))/$B6),"",SUM(_xlfn._xlws.FILTER(RAW_DATA!K:K,EXACT(_xlfn._xlws.FILTER(CONCATENATE(RAW_DATA!$A:$A,RAW_DATA!$B:$B,RAW_DATA!$C:$C),1),$A6)*(RAW_DATA!$T:$T=1)))/$B6)} | S6: {=IF(ISERR(SUM(_xlfn._xlws.FILTER(RAW_DATA!L:L,EXACT(_xlfn._xlws.FILTER(CONCATENATE(RAW_DATA!$A:$A,RAW_DATA!$B:$B,RAW_DATA!$C:$C),1),$A6)*(RAW_DATA!$T:$T=1)))/$B6),"",SUM(_xlfn._xlws.FILTER(RAW_DATA!L:L,EXACT(_xlfn._xlws.FILTER(CONCATENATE(RAW_DATA!$A:$A,RAW_DATA!$B:$B,RAW_DATA!$C:$C),1),$A6)*(RAW_DATA!$T:$T=1)))/$B6)} | T6: {=IF(ISERR(SUM(_xlfn._xlws.FILTER(RAW_DATA!M:M,EXACT(_xlfn._xlws.FILTER(CONCATENATE(RAW_DATA!$A:$A,RAW_DATA!$B:$B,RAW_DATA!$C:$C),1),$A6)*(RAW_DATA!$V:$V=1)))/$D6),"",SUM(_xlfn._xlws.FILTER(RAW_DATA!M:M,EXACT(_xlfn._xlws.FILTER(CONCATENATE(RAW_DATA!$A:$A,RAW_DATA!$B:$B,RAW_DATA!$C:$C),1),$A6)*(RAW_DATA!$V:$V=1)))/$D6)} -> 0.84488889 | U6: {=IF(ISERR(SUM(_xlfn._xlws.FILTER(RAW_DATA!N:N,EXACT(_xlfn._xlws.FILTER(CONCATENATE(RAW_DATA!$A:$A,RAW_DATA!$B:$B,RAW_DATA!$C:$C),1),$A6)*(RAW_DATA!$V:$V=1)))/$D6),"",SUM(_xlfn._xlws.FILTER(RAW_DATA!N:N,EXACT(_xlfn._xlws.FILTER(CONCATENATE(RAW_DATA!$A:$A,RAW_DATA!$B:$B,RAW_DATA!$C:$C),1),$A6)*(RAW_DATA!$V:$V=1)))/$D6)} -> 1.5513333 | V6: {=IF(ISERR(SUM(_xlfn._xlws.FILTER(RAW_DATA!O:O,EXACT(_xlfn._xlws.FILTER(CONCATENATE(RAW_DATA!$A:$A,RAW_DATA!$B:$B,RAW_DATA!$C:$C),1),$A6)*(RAW_DATA!$V:$V=1)))/$D6),"",SUM(_xlfn._xlws.FILTER(RAW_DATA!O:O,EXACT(_xlfn._xlws.FILTER(CONCATENATE(RAW_DATA!$A:$A,RAW_DATA!$B:$B,RAW_DATA!$C:$C),1),$A6)*(RAW_DATA!$V:$V=1)))/$D6)} -> -3.8437444 | W6: {=IF(ISERR(SUM(_xlfn._xlws.FILTER(RAW_DATA!P:P,EXACT(_xlfn._xlws.FILTER(CONCATENATE(RAW_DATA!$A:$A,RAW_DATA!$B:$B,RAW_DATA!$C:$C),1),$A6)*(RAW_DATA!$V:$V=1)))/$D6),"",SUM(_xlfn._xlws.FILTER(RAW_DATA!P:P,EXACT(_xlfn._xlws.FILTER(CONCATENATE(RAW_DATA!$A:$A,RAW_DATA!$B:$B,RAW_DATA!$C:$C),1),$A6)*(RAW_DATA!$V:$V=1)))/$D6)} -> 1.1135556 | X6: {=IF(ISERR(SUM(_xlfn._xlws.FILTER(RAW_DATA!Q:Q,EXACT(_xlfn._xlws.FILTER(CONCATENATE(RAW_DATA!$A:$A,RAW_DATA!$B:$B,RAW_DATA!$C:$C),1),$A6)*(RAW_DATA!$V:$V=1)))/$D6),"",SUM(_xlfn._xlws.FILTER(RAW_DATA!Q:Q,EXACT(_xlfn._xlws.FILTER(CONCATENATE(RAW_DATA!$A:$A,RAW_DATA!$B:$B,RAW_DATA!$C:$C),1),$A6)*(RAW_DATA!$V:$V=1)))/$D6)} -> 10.483951 | Y6: {=IF(ISERR(SUM(_xlfn._xlws.FILTER(RAW_DATA!R:R,EXACT(_xlfn._xlws.FILTER(CONCATENATE(RAW_DATA!$A:$A,RAW_DATA!$B:$B,RAW_DATA!$C:$C),1),$A6)*(RAW_DATA!$V:$V=1)))/$D6),"",SUM(_xlfn._xlws.FILTER(RAW_DATA!R:R,EXACT(_xlfn._xlws.FILTER(CONCATENATE(RAW_DATA!$A:$A,RAW_DATA!$B:$B,RAW_DATA!$C:$C),1),$A6)*(RAW_DATA!$V:$V=1)))/$D6)} -> -0.86155556 | Z6: {=IF(ISERR(SUM(_xlfn._xlws.FILTER(RAW_DATA!S:S,EXACT(_xlfn._xlws.FILTER(CONCATENATE(RAW_DATA!$A:$A,RAW_DATA!$B:$B,RAW_DATA!$C:$C),1),$A6)*(RAW_DATA!$V:$V=1)))/$D6),"",SUM(_xlfn._xlws.FILTER(RAW_DATA!S:S,EXACT(_xlfn._xlws.FILTER(CONCATENATE(RAW_DATA!$A:$A,RAW_DATA!$B:$B,RAW_DATA!$C:$C),1),$A6)*(RAW_DATA!$V:$V=1)))/$D6)} -> 0
A7: NJIT001BasePPCSBattery4_8_CONV_STEP | B7: {=IF(ISERR(SUM(_xlfn._xlws.FILTER(RAW_DATA!$T:$T,EXACT(_xlfn._xlws.FILTER(CONCATENATE(RAW_DATA!$A:$A,RAW_DATA!$B:$B,RAW_DATA!$C:$C),1),$A7)))),"",SUM(_xlfn._xlws.FILTER(RAW_DATA!$T:$T,EXACT(_xlfn._xlws.FILTER(CONCATENATE(RAW_DATA!$A:$A,RAW_DATA!$B:$B,RAW_DATA!$C:$C),1),$A7))))} -> 0 | C7: {=IF(ISERR(SUM(_xlfn._xlws.FILTER(RAW_DATA!$U:$U,EXACT(_xlfn._xlws.FILTER(CONCATENATE(RAW_DATA!$A:$A,RAW_DATA!$B:$B,RAW_DATA!$C:$C),1),$A7)))),"",SUM(_xlfn._xlws.FILTER(RAW_DATA!$U:$U,EXACT(_xlfn._xlws.FILTER(CONCATENATE(RAW_DATA!$A:$A,RAW_DATA!$B:$B,RAW_DATA!$C:$C),1),$A7))))} -> 0 | D7: {=IF(ISERR(SUM(_xlfn._xlws.FILTER(RAW_DATA!$V:$V,EXACT(_xlfn._xlws.FILTER(CONCATENATE(RAW_DATA!$A:$A,RAW_DATA!$B:$B,RAW_DATA!$C:$C),1),$A7)))),"",SUM(_xlfn._xlws.FILTER(RAW_DATA!$V:$V,EXACT(_xlfn._xlws.FILTER(CONCATENATE(RAW_DATA!$A:$A,RAW_DATA!$B:$B,RAW_DATA!$C:$C),1),$A7))))} -> 9 | E7: {=IF(ISERR(SUM(_xlfn._xlws.FILTER(RAW_DATA!$X:$X,EXACT(_xlfn._xlws.FILTER(CONCATENATE(RAW_DATA!$A:$A,RAW_DATA!$B:$B,RAW_DATA!$C:$C),1),$A7)*(RAW_DATA!$T:$T=1)))/$B7),"",SUM(_xlfn._xlws.FILTER(RAW_DATA!$X:$X,EXACT(_xlfn._xlws.FILTER(CONCATENATE(RAW_DATA!$A:$A,RAW_DATA!$B:$B,RAW_DATA!$C:$C),1),$A7)*(RAW_DATA!$T:$T=1)))/$B7)} | F7: {=IF(ISERR(SUM(_xlfn._xlws.FILTER(RAW_DATA!$Y:$Y,EXACT(_xlfn._xlws.FILTER(CONCATENATE(RAW_DATA!$A:$A,RAW_DATA!$B:$B,RAW_DATA!$C:$C),1),$A7)*(RAW_DATA!$U:$U=1)))/$C7),"",SUM(_xlfn._xlws.FILTER(RAW_DATA!$Y:$Y,EXACT(_xlfn._xlws.FILTER(CONCATENATE(RAW_DATA!$A:$A,RAW_DATA!$B:$B,RAW_DATA!$C:$C),1),$A7)*(RAW_DATA!$U:$U=1)))/$C7)} | G7: {=IF(ISERR(SUM(_xlfn._xlws.FILTER(RAW_DATA!$Z:$Z,EXACT(_xlfn._xlws.FILTER(CONCATENATE(RAW_DATA!$A:$A,RAW_DATA!$B:$B,RAW_DATA!$C:$C),1),$A7)*(RAW_DATA!$V:$V=1)))/$D7),"",SUM(_xlfn._xlws.FILTER(RAW_DATA!$Z:$Z,EXACT(_xlfn._xlws.FILTER(CONCATENATE(RAW_DATA!$A:$A,RAW_DATA!$B:$B,RAW_DATA!$C:$C),1),$A7)*(RAW_DATA!$V:$V=1)))/$D7)} -> 20.1925 | H7: {=IF(ISERR(SUM(_xlfn._xlws.FILTER(RAW_DATA!$E:$E,EXACT(_xlfn._xlws.FILTER(CONCATENATE(RAW_DATA!$A:$A,RAW_DATA!$B:$B,RAW_DATA!$C:$C),1),$A7)*(RAW_DATA!T:T=1)))/$B7),"",SUM(_xlfn._xlws.FILTER(RAW_DATA!$E:$E,EXACT(_xlfn._xlws.FILTER(CONCATENATE(RAW_DATA!$A:$A,RAW_DATA!$B:$B,RAW_DATA!$C:$C),1),$A7)*(RAW_DATA!T:T=1)))/$B7)} | I7: {=IF(ISERR(SUM(_xlfn._xlws.FILTER(RAW_DATA!$E:$E,EXACT(_xlfn._xlws.FILTER(CONCATENATE(RAW_DATA!$A:$A,RAW_DATA!$B:$B,RAW_DATA!$C:$C),1),$A7)*(RAW_DATA!U:U=1)))/$C7),"",SUM(_xlfn._xlws.FILTER(RAW_DATA!$E:$E,EXACT(_xlfn._xlws.FILTER(CONCATENATE(RAW_DATA!$A:$A,RAW_DATA!$B:$B,RAW_DATA!$C:$C),1),$A7)*(RAW_DATA!U:U=1)))/$C7)} | J7: {=IF(ISERR(SUM(_xlfn._xlws.FILTER(RAW_DATA!$E:$E,EXACT(_xlfn._xlws.FILTER(CONCATENATE(RAW_DATA!$A:$A,RAW_DATA!$B:$B,RAW_DATA!$C:$C),1),$A7)*(RAW_DATA!V:V=1)))/$D7),"",SUM(_xlfn._xlws.FILTER(RAW_DATA!$E:$E,EXACT(_xlfn._xlws.FILTER(CONCATENATE(RAW_DATA!$A:$A,RAW_DATA!$B:$B,RAW_DATA!$C:$C),1),$A7)*(RAW_DATA!V:V=1)))/$D7)} -> 0 | K7: {=IF(ISERR(SUM(_xlfn._xlws.FILTER(RAW_DATA!$F:$F,EXACT(_xlfn._xlws.FILTER(CONCATENATE(RAW_DATA!$A:$A,RAW_DATA!$B:$B,RAW_DATA!$C:$C),1),$A7)*(RAW_DATA!T:T=1)))/$B7),"",SUM(_xlfn._xlws.FILTER(RAW_DATA!$F:$F,EXACT(_xlfn._xlws.FILTER(CONCATENATE(RAW_DATA!$A:$A,RAW_DATA!$B:$B,RAW_DATA!$C:$C),1),$A7)*(RAW_DATA!T:T=1)))/$B7)} | L7: {=IF(ISERR(SUM(_xlfn._xlws.FILTER(RAW_DATA!$F:$F,EXACT(_xlfn._xlws.FILTER(CONCATENATE(RAW_DATA!$A:$A,RAW_DATA!$B:$B,RAW_DATA!$C:$C),1),$A7)*(RAW_DATA!U:U=1)))/$C7),"",SUM(_xlfn._xlws.FILTER(RAW_DATA!$F:$F,EXACT(_xlfn._xlws.FILTER(CONCATENATE(RAW_DATA!$A:$A,RAW_DATA!$B:$B,RAW_DATA!$C:$C),1),$A7)*(RAW_DATA!U:U=1)))/$C7)} | M7: {=IF(ISERR(SUM(_xlfn._xlws.FILTER(RAW_DATA!$F:$F,EXACT(_xlfn._xlws.FILTER(CONCATENATE(RAW_DATA!$A:$A,RAW_DATA!$B:$B,RAW_DATA!$C:$C),1),$A7)*(RAW_DATA!V:V=1)))/$D7),"",SUM(_xlfn._xlws.FILTER(RAW_DATA!$F:$F,EXACT(_xlfn._xlws.FILTER(CONCATENATE(RAW_DATA!$A:$A,RAW_DATA!$B:$B,RAW_DATA!$C:$C),1),$A7)*(RAW_DATA!V:V=1)))/$D7)} -> 0 | N7: {=IF(ISERR(SUM(_xlfn._xlws.FILTER(RAW_DATA!G:G,EXACT(_xlfn._xlws.FILTER(CONCATENATE(RAW_DATA!$A:$A,RAW_DATA!$B:$B,RAW_DATA!$C:$C),1),$A7)*(RAW_DATA!$T:$T=1)))/$B7),"",SUM(_xlfn._xlws.FILTER(RAW_DATA!G:G,EXACT(_xlfn._xlws.FILTER(CONCATENATE(RAW_DATA!$A:$A,RAW_DATA!$B:$B,RAW_DATA!$C:$C),1),$A7)*(RAW_DATA!$T:$T=1)))/$B7)} | O7: {=IF(ISERR(SUM(_xlfn._xlws.FILTER(RAW_DATA!H:H,EXACT(_xlfn._xlws.FILTER(CONCATENATE(RAW_DATA!$A:$A,RAW_DATA!$B:$B,RAW_DATA!$C:$C),1),$A7)*(RAW_DATA!$T:$T=1)))/$B7),"",SUM(_xlfn._xlws.FILTER(RAW_DATA!H:H,EXACT(_xlfn._xlws.FILTER(CONCATENATE(RAW_DATA!$A:$A,RAW_DATA!$B:$B,RAW_DATA!$C:$C),1),$A7)*(RAW_DATA!$T:$T=1)))/$B7)} | P7: {=IF(ISERR(SUM(_xlfn._xlws.FILTER(RAW_DATA!I:I,EXACT(_xlfn._xlws.FILTER(CONCATENATE(RAW_DATA!$A:$A,RAW_DATA!$B:$B,RAW_DATA!$C:$C),1),$A7)*(RAW_DATA!$T:$T=1)))/$B7),"",SUM(_xlfn._xlws.FILTER(RAW_DATA!I:I,EXACT(_xlfn._xlws.FILTER(CONCATENATE(RAW_DATA!$A:$A,RAW_DATA!$B:$B,RAW_DATA!$C:$C),1),$A7)*(RAW_DATA!$T:$T=1)))/$B7)} | Q7: {=IF(ISERR(SUM(_xlfn._xlws.FILTER(RAW_DATA!J:J,EXACT(_xlfn._xlws.FILTER(CONCATENATE(RAW_DATA!$A:$A,RAW_DATA!$B:$B,RAW_DATA!$C:$C),1),$A7)*(RAW_DATA!$T:$T=1)))/$B7),"",SUM(_xlfn._xlws.FILTER(RAW_DATA!J:J,EXACT(_xlfn._xlws.FILTER(CONCATENATE(RAW_DATA!$A:$A,RAW_DATA!$B:$B,RAW_DATA!$C:$C),1),$A7)*(RAW_DATA!$T:$T=1)))/$B7)} | R7: {=IF(ISERR(SUM(_xlfn._xlws.FILTER(RAW_DATA!K:K,EXACT(_xlfn._xlws.FILTER(CONCATENATE(RAW_DATA!$A:$A,RAW_DATA!$B:$B,RAW_DATA!$C:$C),1),$A7)*(RAW_DATA!$T:$T=1)))/$B7),"",SUM(_xlfn._xlws.FILTER(RAW_DATA!K:K,EXACT(_xlfn._xlws.FILTER(CONCATENATE(RAW_DATA!$A:$A,RAW_DATA!$B:$B,RAW_DATA!$C:$C),1),$A7)*(RAW_DATA!$T:$T=1)))/$B7)} | S7: {=IF(ISERR(SUM(_xlfn._xlws.FILTER(RAW_DATA!L:L,EXACT(_xlfn._xlws.FILTER(CONCATENATE(RAW_DATA!$A:$A,RAW_DATA!$B:$B,RAW_DATA!$C:$C),1),$A7)*(RAW_DATA!$T:$T=1)))/$B7),"",SUM(_xlfn._xlws.FILTER(RAW_DATA!L:L,EXACT(_xlfn._xlws.FILTER(CONCATENATE(RAW_DATA!$A:$A,RAW_DATA!$B:$B,RAW_DATA!$C:$C),1),$A7)*(RAW_DATA!$T:$T=1)))/$B7)} | T7: {=IF(ISERR(SUM(_xlfn._xlws.FILTER(RAW_DATA!M:M,EXACT(_xlfn._xlws.FILTER(CONCATENATE(RAW_DATA!$A:$A,RAW_DATA!$B:$B,RAW_DATA!$C:$C),1),$A7)*(RAW_DATA!$V:$V=1)))/$D7),"",SUM(_xlfn._xlws.FILTER(RAW_DATA!M:M,EXACT(_xlfn._xlws.FILTER(CONCATENATE(RAW_DATA!$A:$A,RAW_DATA!$B:$B,RAW_DATA!$C:$C),1),$A7)*(RAW_DATA!$V:$V=1)))/$D7)} -> 0.76311111 | U7: {=IF(ISERR(SUM(_xlfn._xlws.FILTER(RAW_DATA!N:N,EXACT(_xlfn._xlws.FILTER(CONCATENATE(RAW_DATA!$A:$A,RAW_DATA!$B:$B,RAW_DATA!$C:$C),1),$A7)*(RAW_DATA!$V:$V=1)))/$D7),"",SUM(_xlfn._xlws.FILTER(RAW_DATA!N:N,EXACT(_xlfn._xlws.FILTER(CONCATENATE(RAW_DATA!$A:$A,RAW_DATA!$B:$B,RAW_DATA!$C:$C),1),$A7)*(RAW_DATA!$V:$V=1)))/$D7)} -> 1.5597778 | V7: {=IF(ISERR(SUM(_xlfn._xlws.FILTER(RAW_DATA!O:O,EXACT(_xlfn._xlws.FILTER(CONCATENATE(RAW_DATA!$A:$A,RAW_DATA!$B:$B,RAW_DATA!$C:$C),1),$A7)*(RAW_DATA!$V:$V=1)))/$D7),"",SUM(_xlfn._xlws.FILTER(RAW_DATA!O:O,EXACT(_xlfn._xlws.FILTER(CONCATENATE(RAW_DATA!$A:$A,RAW_DATA!$B:$B,RAW_DATA!$C:$C),1),$A7)*(RAW_DATA!$V:$V=1)))/$D7)} -> -2.0464556 | W7: {=IF(ISERR(SUM(_xlfn._xlws.FILTER(RAW_DATA!P:P,EXACT(_xlfn._xlws.FILTER(CONCATENATE(RAW_DATA!$A:$A,RAW_DATA!$B:$B,RAW_DATA!$C:$C),1),$A7)*(RAW_DATA!$V:$V=1)))/$D7),"",SUM(_xlfn._xlws.FILTER(RAW_DATA!P:P,EXACT(_xlfn._xlws.FILTER(CONCATENATE(RAW_DATA!$A:$A,RAW_DATA!$B:$B,RAW_DATA!$C:$C),1),$A7)*(RAW_DATA!$V:$V=1)))/$D7)} -> 1.1293333 | X7: {=IF(ISERR(SUM(_xlfn._xlws.FILTER(RAW_DATA!Q:Q,EXACT(_xlfn._xlws.FILTER(CONCATENATE(RAW_DATA!$A:$A,RAW_DATA!$B:$B,RAW_DATA!$C:$C),1),$A7)*(RAW_DATA!$V:$V=1)))/$D7),"",SUM(_xlfn._xlws.FILTER(RAW_DATA!Q:Q,EXACT(_xlfn._xlws.FILTER(CONCATENATE(RAW_DATA!$A:$A,RAW_DATA!$B:$B,RAW_DATA!$C:$C),1),$A7)*(RAW_DATA!$V:$V=1)))/$D7)} -> 7.2765667 | Y7: {=IF(ISERR(SUM(_xlfn._xlws.FILTER(RAW_DATA!R:R,EXACT(_xlfn._xlws.FILTER(CONCATENATE(RAW_DATA!$A:$A,RAW_DATA!$B:$B,RAW_DATA!$C:$C),1),$A7)*(RAW_DATA!$V:$V=1)))/$D7),"",SUM(_xlfn._xlws.FILTER(RAW_DATA!R:R,EXACT(_xlfn._xlws.FILTER(CONCATENATE(RAW_DATA!$A:$A,RAW_DATA!$B:$B,RAW_DATA!$C:$C),1),$A7)*(RAW_DATA!$V:$V=1)))/$D7)} -> -1.428 | Z7: {=IF(ISERR(SUM(_xlfn._xlws.FILTER(RAW_DATA!S:S,EXACT(_xlfn._xlws.FILTER(CONCATENATE(RAW_DATA!$A:$A,RAW_DATA!$B:$B,RAW_DATA!$C:$C),1),$A7)*(RAW_DATA!$V:$V=1)))/$D7),"",SUM(_xlfn._xlws.FILTER(RAW_DATA!S:S,EXACT(_xlfn._xlws.FILTER(CONCATENATE(RAW_DATA!$A:$A,RAW_DATA!$B:$B,RAW_DATA!$C:$C),1),$A7)*(RAW_DATA!$V:$V=1)))/$D7)} -> 0
A8: NJIT002BasePPCSBattery4_8_CONV_STEP | B8: {=IF(ISERR(SUM(_xlfn._xlws.FILTER(RAW_DATA!$T:$T,EXACT(_xlfn._xlws.FILTER(CONCATENATE(RAW_DATA!$A:$A,RAW_DATA!$B:$B,RAW_DATA!$C:$C),1),$A8)))),"",SUM(_xlfn._xlws.FILTER(RAW_DATA!$T:$T,EXACT(_xlfn._xlws.FILTER(CONCATENATE(RAW_DATA!$A:$A,RAW_DATA!$B:$B,RAW_DATA!$C:$C),1),$A8))))} -> 0 | C8: {=IF(ISERR(SUM(_xlfn._xlws.FILTER(RAW_DATA!$U:$U,EXACT(_xlfn._xlws.FILTER(CONCATENATE(RAW_DATA!$A:$A,RAW_DATA!$B:$B,RAW_DATA!$C:$C),1),$A8)))),"",SUM(_xlfn._xlws.FILTER(RAW_DATA!$U:$U,EXACT(_xlfn._xlws.FILTER(CONCATENATE(RAW_DATA!$A:$A,RAW_DATA!$B:$B,RAW_DATA!$C:$C),1),$A8))))} -> 0 | D8: {=IF(ISERR(SUM(_xlfn._xlws.FILTER(RAW_DATA!$V:$V,EXACT(_xlfn._xlws.FILTER(CONCATENATE(RAW_DATA!$A:$A,RAW_DATA!$B:$B,RAW_DATA!$C:$C),1),$A8)))),"",SUM(_xlfn._xlws.FILTER(RAW_DATA!$V:$V,EXACT(_xlfn._xlws.FILTER(CONCATENATE(RAW_DATA!$A:$A,RAW_DATA!$B:$B,RAW_DATA!$C:$C),1),$A8))))} -> 2 | E8: {=IF(ISERR(SUM(_xlfn._xlws.FILTER(RAW_DATA!$X:$X,EXACT(_xlfn._xlws.FILTER(CONCATENATE(RAW_DATA!$A:$A,RAW_DATA!$B:$B,RAW_DATA!$C:$C),1),$A8)*(RAW_DATA!$T:$T=1)))/$B8),"",SUM(_xlfn._xlws.FILTER(RAW_DATA!$X:$X,EXACT(_xlfn._xlws.FILTER(CONCATENATE(RAW_DATA!$A:$A,RAW_DATA!$B:$B,RAW_DATA!$C:$C),1),$A8)*(RAW_DATA!$T:$T=1)))/$B8)} | F8: {=IF(ISERR(SUM(_xlfn._xlws.FILTER(RAW_DATA!$Y:$Y,EXACT(_xlfn._xlws.FILTER(CONCATENATE(RAW_DATA!$A:$A,RAW_DATA!$B:$B,RAW_DATA!$C:$C),1),$A8)*(RAW_DATA!$U:$U=1)))/$C8),"",SUM(_xlfn._xlws.FILTER(RAW_DATA!$Y:$Y,EXACT(_xlfn._xlws.FILTER(CONCATENATE(RAW_DATA!$A:$A,RAW_DATA!$B:$B,RAW_DATA!$C:$C),1),$A8)*(RAW_DATA!$U:$U=1)))/$C8)} | G8: {=IF(ISERR(SUM(_xlfn._xlws.FILTER(RAW_DATA!$Z:$Z,EXACT(_xlfn._xlws.FILTER(CONCATENATE(RAW_DATA!$A:$A,RAW_DATA!$B:$B,RAW_DATA!$C:$C),1),$A8)*(RAW_DATA!$V:$V=1)))/$D8),"",SUM(_xlfn._xlws.FILTER(RAW_DATA!$Z:$Z,EXACT(_xlfn._xlws.FILTER(CONCATENATE(RAW_DATA!$A:$A,RAW_DATA!$B:$B,RAW_DATA!$C:$C),1),$A8)*(RAW_DATA!$V:$V=1)))/$D8)} -> 20.1925 | H8: {=IF(ISERR(SUM(_xlfn._xlws.FILTER(RAW_DATA!$E:$E,EXACT(_xlfn._xlws.FILTER(CONCATENATE(RAW_DATA!$A:$A,RAW_DATA!$B:$B,RAW_DATA!$C:$C),1),$A8)*(RAW_DATA!T:T=1)))/$B8),"",SUM(_xlfn._xlws.FILTER(RAW_DATA!$E:$E,EXACT(_xlfn._xlws.FILTER(CONCATENATE(RAW_DATA!$A:$A,RAW_DATA!$B:$B,RAW_DATA!$C:$C),1),$A8)*(RAW_DATA!T:T=1)))/$B8)} | I8: {=IF(ISERR(SUM(_xlfn._xlws.FILTER(RAW_DATA!$E:$E,EXACT(_xlfn._xlws.FILTER(CONCATENATE(RAW_DATA!$A:$A,RAW_DATA!$B:$B,RAW_DATA!$C:$C),1),$A8)*(RAW_DATA!U:U=1)))/$C8),"",SUM(_xlfn._xlws.FILTER(RAW_DATA!$E:$E,EXACT(_xlfn._xlws.FILTER(CONCATENATE(RAW_DATA!$A:$A,RAW_DATA!$B:$B,RAW_DATA!$C:$C),1),$A8)*(RAW_DATA!U:U=1)))/$C8)} | J8: {=IF(ISERR(SUM(_xlfn._xlws.FILTER(RAW_DATA!$E:$E,EXACT(_xlfn._xlws.FILTER(CONCATENATE(RAW_DATA!$A:$A,RAW_DATA!$B:$B,RAW_DATA!$C:$C),1),$A8)*(RAW_DATA!V:V=1)))/$D8),"",SUM(_xlfn._xlws.FILTER(RAW_DATA!$E:$E,EXACT(_xlfn._xlws.FILTER(CONCATENATE(RAW_DATA!$A:$A,RAW_DATA!$B:$B,RAW_DATA!$C:$C),1),$A8)*(RAW_DATA!V:V=1)))/$D8)} -> 0 | K8: {=IF(ISERR(SUM(_xlfn._xlws.FILTER(RAW_DATA!$F:$F,EXACT(_xlfn._xlws.FILTER(CONCATENATE(RAW_DATA!$A:$A,RAW_DATA!$B:$B,RAW_DATA!$C:$C),1),$A8)*(RAW_DATA!T:T=1)))/$B8),"",SUM(_xlfn._xlws.FILTER(RAW_DATA!$F:$F,EXACT(_xlfn._xlws.FILTER(CONCATENATE(RAW_DATA!$A:$A,RAW_DATA!$B:$B,RAW_DATA!$C:$C),1),$A8)*(RAW_DATA!T:T=1)))/$B8)} | L8: {=IF(ISERR(SUM(_xlfn._xlws.FILTER(RAW_DATA!$F:$F,EXACT(_xlfn._xlws.FILTER(CONCATENATE(RAW_DATA!$A:$A,RAW_DATA!$B:$B,RAW_DATA!$C:$C),1),$A8)*(RAW_DATA!U:U=1)))/$C8),"",SUM(_xlfn._xlws.FILTER(RAW_DATA!$F:$F,EXACT(_xlfn._xlws.FILTER(CONCATENATE(RAW_DATA!$A:$A,RAW_DATA!$B:$B,RAW_DATA!$C:$C),1),$A8)*(RAW_DATA!U:U=1)))/$C8)} | M8: {=IF(ISERR(SUM(_xlfn._xlws.FILTER(RAW_DATA!$F:$F,EXACT(_xlfn._xlws.FILTER(CONCATENATE(RAW_DATA!$A:$A,RAW_DATA!$B:$B,RAW_DATA!$C:$C),1),$A8)*(RAW_DATA!V:V=1)))/$D8),"",SUM(_xlfn._xlws.FILTER(RAW_DATA!$F:$F,EXACT(_xlfn._xlws.FILTER(CONCATENATE(RAW_DATA!$A:$A,RAW_DATA!$B:$B,RAW_DATA!$C:$C),1),$A8)*(RAW_DATA!V:V=1)))/$D8)} -> 0.5 | N8: {=IF(ISERR(SUM(_xlfn._xlws.FILTER(RAW_DATA!G:G,EXACT(_xlfn._xlws.FILTER(CONCATENATE(RAW_DATA!$A:$A,RAW_DATA!$B:$B,RAW_DATA!$C:$C),1),$A8)*(RAW_DATA!$T:$T=1)))/$B8),"",SUM(_xlfn._xlws.FILTER(RAW_DATA!G:G,EXACT(_xlfn._xlws.FILTER(CONCATENATE(RAW_DATA!$A:$A,RAW_DATA!$B:$B,RAW_DATA!$C:$C),1),$A8)*(RAW_DATA!$T:$T=1)))/$B8)} | O8: {=IF(ISERR(SUM(_xlfn._xlws.FILTER(RAW_DATA!H:H,EXACT(_xlfn._xlws.FILTER(CONCATENATE(RAW_DATA!$A:$A,RAW_DATA!$B:$B,RAW_DATA!$C:$C),1),$A8)*(RAW_DATA!$T:$T=1)))/$B8),"",SUM(_xlfn._xlws.FILTER(RAW_DATA!H:H,EXACT(_xlfn._xlws.FILTER(CONCATENATE(RAW_DATA!$A:$A,RAW_DATA!$B:$B,RAW_DATA!$C:$C),1),$A8)*(RAW_DATA!$T:$T=1)))/$B8)} | P8: {=IF(ISERR(SUM(_xlfn._xlws.FILTER(RAW_DATA!I:I,EXACT(_xlfn._xlws.FILTER(CONCATENATE(RAW_DATA!$A:$A,RAW_DATA!$B:$B,RAW_DATA!$C:$C),1),$A8)*(RAW_DATA!$T:$T=1)))/$B8),"",SUM(_xlfn._xlws.FILTER(RAW_DATA!I:I,EXACT(_xlfn._xlws.FILTER(CONCATENATE(RAW_DATA!$A:$A,RAW_DATA!$B:$B,RAW_DATA!$C:$C),1),$A8)*(RAW_DATA!$T:$T=1)))/$B8)} | Q8: {=IF(ISERR(SUM(_xlfn._xlws.FILTER(RAW_DATA!J:J,EXACT(_xlfn._xlws.FILTER(CONCATENATE(RAW_DATA!$A:$A,RAW_DATA!$B:$B,RAW_DATA!$C:$C),1),$A8)*(RAW_DATA!$T:$T=1)))/$B8),"",SUM(_xlfn._xlws.FILTER(RAW_DATA!J:J,EXACT(_xlfn._xlws.FILTER(CONCATENATE(RAW_DATA!$A:$A,RAW_DATA!$B:$B,RAW_DATA!$C:$C),1),$A8)*(RAW_DATA!$T:$T=1)))/$B8)} | R8: {=IF(ISERR(SUM(_xlfn._xlws.FILTER(RAW_DATA!K:K,EXACT(_xlfn._xlws.FILTER(CONCATENATE(RAW_DATA!$A:$A,RAW_DATA!$B:$B,RAW_DATA!$C:$C),1),$A8)*(RAW_DATA!$T:$T=1)))/$B8),"",SUM(_xlfn._xlws.FILTER(RAW_DATA!K:K,EXACT(_xlfn._xlws.FILTER(CONCATENATE(RAW_DATA!$A:$A,RAW_DATA!$B:$B,RAW_DATA!$C:$C),1),$A8)*(RAW_DATA!$T:$T=1)))/$B8)} | S8: {=IF(ISERR(SUM(_xlfn._xlws.FILTER(RAW_DATA!L:L,EXACT(_xlfn._xlws.FILTER(CONCATENATE(RAW_DATA!$A:$A,RAW_DATA!$B:$B,RAW_DATA!$C:$C),1),$A8)*(RAW_DATA!$T:$T=1)))/$B8),"",SUM(_xlfn._xlws.FILTER(RAW_DATA!L:L,EXACT(_xlfn._xlws.FILTER(CONCATENATE(RAW_DATA!$A:$A,RAW_DATA!$B:$B,RAW_DATA!$C:$C),1),$A8)*(RAW_DATA!$T:$T=1)))/$B8)} | T8: {=IF(ISERR(SUM(_xlfn._xlws.FILTER(RAW_DATA!M:M,EXACT(_xlfn._xlws.FILTER(CONCATENATE(RAW_DATA!$A:$A,RAW_DATA!$B:$B,RAW_DATA!$C:$C),1),$A8)*(RAW_DATA!$V:$V=1)))/$D8),"",SUM(_xlfn._xlws.FILTER(RAW_DATA!M:M,EXACT(_xlfn._xlws.FILTER(CONCATENATE(RAW_DATA!$A:$A,RAW_DATA!$B:$B,RAW_DATA!$C:$C),1),$A8)*(RAW_DATA!$V:$V=1)))/$D8)} -> 0.745 | U8: {=IF(ISERR(SUM(_xlfn._xlws.FILTER(RAW_DATA!N:N,EXACT(_xlfn._xlws.FILTER(CONCATENATE(RAW_DATA!$A:$A,RAW_DATA!$B:$B,RAW_DATA!$C:$C),1),$A8)*(RAW_DATA!$V:$V=1)))/$D8),"",SUM(_xlfn._xlws.FILTER(RAW_DATA!N:N,EXACT(_xlfn._xlws.FILTER(CONCATENATE(RAW_DATA!$A:$A,RAW_DATA!$B:$B,RAW_DATA!$C:$C),1),$A8)*(RAW_DATA!$V:$V=1)))/$D8)} -> 1.195 | V8: {=IF(ISERR(SUM(_xlfn._xlws.FILTER(RAW_DATA!O:O,EXACT(_xlfn._xlws.FILTER(CONCATENATE(RAW_DATA!$A:$A,RAW_DATA!$B:$B,RAW_DATA!$C:$C),1),$A8)*(RAW_DATA!$V:$V=1)))/$D8),"",SUM(_xlfn._xlws.FILTER(RAW_DATA!O:O,EXACT(_xlfn._xlws.FILTER(CONCATENATE(RAW_DATA!$A:$A,RAW_DATA!$B:$B,RAW_DATA!$C:$C),1),$A8)*(RAW_DATA!$V:$V=1)))/$D8)} -> -1.748585 | W8: {=IF(ISERR(SUM(_xlfn._xlws.FILTER(RAW_DATA!P:P,EXACT(_xlfn._xlws.FILTER(CONCATENATE(RAW_DATA!$A:$A,RAW_DATA!$B:$B,RAW_DATA!$C:$C),1),$A8)*(RAW_DATA!$V:$V=1)))/$D8),"",SUM(_xlfn._xlws.FILTER(RAW_DATA!P:P,EXACT(_xlfn._xlws.FILTER(CONCATENATE(RAW_DATA!$A:$A,RAW_DATA!$B:$B,RAW_DATA!$C:$C),1),$A8)*(RAW_DATA!$V:$V=1)))/$D8)} -> 1.037 | X8: {=IF(ISERR(SUM(_xlfn._xlws.FILTER(RAW_DATA!Q:Q,EXACT(_xlfn._xlws.FILTER(CONCATENATE(RAW_DATA!$A:$A,RAW_DATA!$B:$B,RAW_DATA!$C:$C),1),$A8)*(RAW_DATA!$V:$V=1)))/$D8),"",SUM(_xlfn._xlws.FILTER(RAW_DATA!Q:Q,EXACT(_xlfn._xlws.FILTER(CONCATENATE(RAW_DATA!$A:$A,RAW_DATA!$B:$B,RAW_DATA!$C:$C),1),$A8)*(RAW_DATA!$V:$V=1)))/$D8)} -> 6.11336 | Y8: {=IF(ISERR(SUM(_xlfn._xlws.FILTER(RAW_DATA!R:R,EXACT(_xlfn._xlws.FILTER(CONCATENATE(RAW_DATA!$A:$A,RAW_DATA!$B:$B,RAW_DATA!$C:$C),1),$A8)*(RAW_DATA!$V:$V=1)))/$D8),"",SUM(_xlfn._xlws.FILTER(RAW_DATA!R:R,EXACT(_xlfn._xlws.FILTER(CONCATENATE(RAW_DATA!$A:$A,RAW_DATA!$B:$B,RAW_DATA!$C:$C),1),$A8)*(RAW_DATA!$V:$V=1)))/$D8)} -> -0.835 | Z8: {=IF(ISERR(SUM(_xlfn._xlws.FILTER(RAW_DATA!S:S,EXACT(_xlfn._xlws.FILTER(CONCATENATE(RAW_DATA!$A:$A,RAW_DATA!$B:$B,RAW_DATA!$C:$C),1),$A8)*(RAW_DATA!$V:$V=1)))/$D8),"",SUM(_xlfn._xlws.FILTER(RAW_DATA!S:S,EXACT(_xlfn._xlws.FILTER(CONCATENATE(RAW_DATA!$A:$A,RAW_DATA!$B:$B,RAW_DATA!$C:$C),1),$A8)*(RAW_DATA!$V:$V=1)))/$D8)} -> 0
